Workbook
Name List_StaffID: Parameter!$F$2:$F$51
Name vMonthSelected: Parameter!$S$2
Name dataJobIn: 'Job-In'!$A$6:$BH$1004
Name data_Staff: Parameter!$F$2:$H$51
Name List_Holidays: Parameter!$M$2:$M$1002
Name JobName: 'Job-In'!$C$6:$C$1004
Name List_Nickname: Parameter!$I$2:$I$51
Name cLunchBegin: Parameter!$Q$7
Name List_WeekHolidays: Parameter!$L$2:$L$7
Name List_DayType: Parameter!$K$2:$K$11
Name cLunchEnd: Parameter!$Q$8
Name vDurationWork: Parameter!$S$6
Name vStaffSelected: Parameter!$S$9
Name List_Month: Parameter!$B$2:$B$13
Name JobID: 'Job-In'!$A$6:$A$1004
Name cWorkBegin: Parameter!$Q$5
Name List_HolidaysDesc: Parameter!$N$2:$N$1002
Name vYearSelected: Parameter!$S$3
Name List_Date: Parameter!$D$2:$D$32
Name List_StaffName: Parameter!$H$2:$H$51
Name vDurationLunch: Parameter!$S$7
Name cWorkEnd: Parameter!$Q$6
Name JobDate: 'Job-In'!$M$6:$M$1004
Name List_FingerID: Parameter!$G$2:$G$51
Name cDinnerBegin: Parameter!$Q$9
Name cDinnerEnd: Parameter!$Q$10
Name vDateSelected: Parameter!$S$5
Name List_JobName: JobList!$C$3:$C$1000
Name vDurationDinner: Parameter!$S$8
Name List_Weekday: Parameter!$C$2:$C$8

Sheet Job-In
A1: 1 | B1: 2 | C1: 3 | D1: 4 | E1: 5 | F1: 6 | G1: 7 | H1: 8 | I1: 9 | J1: 10 | K1: 11 | L1: 12 | M1: 13 | N1: 14 | O1: 15 | P1: 16 | Q1: 17 | R1: 18 | S1: 19 | T1: 20 | U1: 21
A2: =IFERROR(__xludf.DUMMYFUNCTION("ROWS(FILTER(B6:B1506,Not(ISBLANK(B6:B1506))+NOT(ISBLANK(C6:C1506))+NOT(ISBLANK(D6:D1506))))"),147.0) -> 147 | B2: งาน | U2: =IFERROR(__xludf.DUMMYFUNCTION("SPARKLINE(U$3,{""charttype"",""column"";""ymin"",MIN($U$3:$BD$3);""ymax"",MAX($U$3:$BD$3);""color"",""blue""})"),"") | V2: =IFERROR(__xludf.DUMMYFUNCTION("SPARKLINE(V$3,{""charttype"",""column"";""ymin"",MIN($U$3:$BD$3);""ymax"",MAX($U$3:$BD$3);""color"",""blue""})"),"") | W2: =IFERROR(__xludf.DUMMYFUNCTION("SPARKLINE(W$3,{""charttype"",""column"";""ymin"",MIN($U$3:$BD$3);""ymax"",MAX($U$3:$BD$3);""color"",""blue""})"),"") | X2: =IFERROR(__xludf.DUMMYFUNCTION("SPARKLINE(X$3,{""charttype"",""column"";""ymin"",MIN($U$3:$BD$3);""ymax"",MAX($U$3:$BD$3);""color"",""blue""})"),"") | Y2: =IFERROR(__xludf.DUMMYFUNCTION("SPARKLINE(Y$3,{""charttype"",""column"";""ymin"",MIN($U$3:$BD$3);""ymax"",MAX($U$3:$BD$3);""color"",""blue""})"),"") | Z2: =IFERROR(__xludf.DUMMYFUNCTION("SPARKLINE(Z$3,{""charttype"",""column"";""ymin"",MIN($U$3:$BD$3);""ymax"",MAX($U$3:$BD$3);""color"",""blue""})"),"") | AA2: =IFERROR(__xludf.DUMMYFUNCTION("SPARKLINE(AA$3,{""charttype"",""column"";""ymin"",MIN($U$3:$BD$3);""ymax"",MAX($U$3:$BD$3);""color"",""blue""})"),"") | AB2: =IFERROR(__xludf.DUMMYFUNCTION("SPARKLINE(AB$3,{""charttype"",""column"";""ymin"",MIN($U$3:$BD$3);""ymax"",MAX($U$3:$BD$3);""color"",""blue""})"),"") | AC2: =IFERROR(__xludf.DUMMYFUNCTION("SPARKLINE(AC$3,{""charttype"",""column"";""ymin"",MIN($U$3:$BD$3);""ymax"",MAX($U$3:$BD$3);""color"",""blue""})"),"") | AD2: =IFERROR(__xludf.DUMMYFUNCTION("SPARKLINE(AD$3,{""charttype"",""column"";""ymin"",MIN($U$3:$BD$3);""ymax"",MAX($U$3:$BD$3);""color"",""blue""})"),"") | AE2: =IFERROR(__xludf.DUMMYFUNCTION("SPARKLINE(AE$3,{""charttype"",""column"";""ymin"",MIN($U$3:$BD$3);""ymax"",MAX($U$3:$BD$3);""color"",""blue""})"),"") | AF2: =IFERROR(__xludf.DUMMYFUNCTION("SPARKLINE(AF$3,{""charttype"",""column"";""ymin"",MIN($U$3:$BD$3);""ymax"",MAX($U$3:$BD$3);""color"",""blue""})"),"") | AG2: =IFERROR(__xludf.DUMMYFUNCTION("SPARKLINE(AG$3,{""charttype"",""column"";""ymin"",MIN($U$3:$BD$3);""ymax"",MAX($U$3:$BD$3);""color"",""blue""})"),"") | AH2: =IFERROR(__xludf.DUMMYFUNCTION("SPARKLINE(AH$3,{""charttype"",""column"";""ymin"",MIN($U$3:$BD$3);""ymax"",MAX($U$3:$BD$3);""color"",""blue""})"),"") | AI2: =IFERROR(__xludf.DUMMYFUNCTION("SPARKLINE(AI$3,{""charttype"",""column"";""ymin"",MIN($U$3:$BD$3);""ymax"",MAX($U$3:$BD$3);""color"",""blue""})"),"") | AJ2: =IFERROR(__xludf.DUMMYFUNCTION("SPARKLINE(AJ$3,{""charttype"",""column"";""ymin"",MIN($U$3:$BD$3);""ymax"",MAX($U$3:$BD$3);""color"",""blue""})"),"") | AK2: =IFERROR(__xludf.DUMMYFUNCTION("SPARKLINE(AK$3,{""charttype"",""column"";""ymin"",MIN($U$3:$BD$3);""ymax"",MAX($U$3:$BD$3);""color"",""blue""})"),"") | AL2: =IFERROR(__xludf.DUMMYFUNCTION("SPARKLINE(AL$3,{""charttype"",""column"";""ymin"",MIN($U$3:$BD$3);""ymax"",MAX($U$3:$BD$3);""color"",""blue""})"),"") | AM2: =IFERROR(__xludf.DUMMYFUNCTION("SPARKLINE(AM$3,{""charttype"",""column"";""ymin"",MIN($U$3:$BD$3);""ymax"",MAX($U$3:$BD$3);""color"",""blue""})"),"") | AN2: =IFERROR(__xludf.DUMMYFUNCTION("SPARKLINE(AN$3,{""charttype"",""column"";""ymin"",MIN($U$3:$BD$3);""ymax"",MAX($U$3:$BD$3);""color"",""blue""})"),"") | AO2: =IFERROR(__xludf.DUMMYFUNCTION("SPARKLINE(AO$3,{""charttype"",""column"";""ymin"",MIN($U$3:$BD$3);""ymax"",MAX($U$3:$BD$3);""color"",""blue""})"),"") | AP2: =IFERROR(__xludf.DUMMYFUNCTION("SPARKLINE(AP$3,{""charttype"",""column"";""ymin"",MIN($U$3:$BD$3);""ymax"",MAX($U$3:$BD$3);""color"",""blue""})"),"") | AQ2: =IFERROR(__xludf.DUMMYFUNCTION("SPARKLINE(AQ$3,{""charttype"",""column"";""ymin"",MIN($U$3:$BD$3);""ymax"",MAX($U$3:$BD$3);""color"",""blue""})"),"") | AR2: =IFERROR(__xludf.DUMMYFUNCTION("SPARKLINE(AR$3,{""charttype"",""column"";""ymin"",MIN($U$3:$BD$3);""ymax"",MAX($U$3:$BD$3);""color"",""blue""})"),"") | AS2: =IFERROR(__xludf.DUMMYFUNCTION("SPARKLINE(AS$3,{""charttype"",""column"";""ymin"",MIN($U$3:$BD$3);""ymax"",MAX($U$3:$BD$3);""color"",""blue""})"),"") | AT2: =IFERROR(__xludf.DUMMYFUNCTION("SPARKLINE(AT$3,{""charttype"",""column"";""ymin"",MIN($U$3:$BD$3);""ymax"",MAX($U$3:$BD$3);""color"",""blue""})"),"") | AU2: =IFERROR(__xludf.DUMMYFUNCTION("SPARKLINE(AU$3,{""charttype"",""column"";""ymin"",MIN($U$3:$BD$3);""ymax"",MAX($U$3:$BD$3);""color"",""blue""})"),"") | AV2: =IFERROR(__xludf.DUMMYFUNCTION("SPARKLINE(AV$3,{""charttype"",""column"";""ymin"",MIN($U$3:$BD$3);""ymax"",MAX($U$3:$BD$3);""color"",""blue""})"),"") | AW2: =IFERROR(__xludf.DUMMYFUNCTION("SPARKLINE(AW$3,{""charttype"",""column"";""ymin"",MIN($U$3:$BD$3);""ymax"",MAX($U$3:$BD$3);""color"",""blue""})"),"") | AX2: =IFERROR(__xludf.DUMMYFUNCTION("SPARKLINE(AX$3,{""charttype"",""column"";""ymin"",MIN($U$3:$BD$3);""ymax"",MAX($U$3:$BD$3);""color"",""blue""})"),"") | AY2: =IFERROR(__xludf.DUMMYFUNCTION("SPARKLINE(AY$3,{""charttype"",""column"";""ymin"",MIN($U$3:$BD$3);""ymax"",MAX($U$3:$BD$3);""color"",""blue""})"),"") | AZ2: =IFERROR(__xludf.DUMMYFUNCTION("SPARKLINE(AZ$3,{""charttype"",""column"";""ymin"",MIN($U$3:$BD$3);""ymax"",MAX($U$3:$BD$3);""color"",""blue""})"),"") | BA2: =IFERROR(__xludf.DUMMYFUNCTION("SPARKLINE(BA$3,{""charttype"",""column"";""ymin"",MIN($U$3:$BD$3);""ymax"",MAX($U$3:$BD$3);""color"",""blue""})"),"") | BB2: =IFERROR(__xludf.DUMMYFUNCTION("SPARKLINE(BB$3,{""charttype"",""column"";""ymin"",MIN($U$3:$BD$3);""ymax"",MAX($U$3:$BD$3);""color"",""blue""})"),"") | BC2: =IFERROR(__xludf.DUMMYFUNCTION("SPARKLINE(BC$3,{""charttype"",""column"";""ymin"",MIN($U$3:$BD$3);""ymax"",MAX($U$3:$BD$3);""color"",""blue""})"),"") | BD2: =IFERROR(__xludf.DUMMYFUNCTION("SPARKLINE(BD$3,{""charttype"",""column"";""ymin"",MIN($U$3:$BD$3);""ymax"",MAX($U$3:$BD$3);""color"",""blue""})"),"") | BE2: =IFERROR(__xludf.DUMMYFUNCTION("SPARKLINE(BE$3,{""charttype"",""column"";""ymin"",MIN($U$3:$BD$3);""ymax"",MAX($U$3:$BD$3);""color"",""blue""})"),"") | BF2: =IFERROR(__xludf.DUMMYFUNCTION("SPARKLINE(BF$3,{""charttype"",""column"";""ymin"",MIN($U$3:$BD$3);""ymax"",MAX($U$3:$BD$3);""color"",""blue""})"),"") | BG2: =IFERROR(__xludf.DUMMYFUNCTION("SPARKLINE(BG$3,{""charttype"",""column"";""ymin"",MIN($U$3:$BD$3);""ymax"",MAX($U$3:$BD$3);""color"",""blue""})"),"") | BH2: =IFERROR(__xludf.DUMMYFUNCTION("SPARKLINE(BH$3,{""charttype"",""column"";""ymin"",MIN($U$3:$BD$3);""ymax"",MAX($U$3:$BD$3);""color"",""blue""})"),"") | BI2: =IFERROR(__xludf.DUMMYFUNCTION("SPARKLINE(BI$3,{""charttype"",""column"";""ymin"",MIN($U$3:$BD$3);""ymax"",MAX($U$3:$BD$3);""color"",""blue""})"),"") | BJ2: =IFERROR(__xludf.DUMMYFUNCTION("SPARKLINE(BJ$3,{""charttype"",""column"";""ymin"",MIN($U$3:$BD$3);""ymax"",MAX($U$3:$BD$3);""color"",""blue""})"),"") | BK2: =IFERROR(__xludf.DUMMYFUNCTION("SPARKLINE(BK$3,{""charttype"",""column"";""ymin"",MIN($U$3:$BD$3);""ymax"",MAX($U$3:$BD$3);""color"",""blue""})"),"") | BL2: =IFERROR(__xludf.DUMMYFUNCTION("SPARKLINE(BL$3,{""charttype"",""column"";""ymin"",MIN($U$3:$BD$3);""ymax"",MAX($U$3:$BD$3);""color"",""blue""})"),"") | BM2: =IFERROR(__xludf.DUMMYFUNCTION("SPARKLINE(BM$3,{""charttype"",""column"";""ymin"",MIN($U$3:$BD$3);""ymax"",MAX($U$3:$BD$3);""color"",""blue""})"),"") | BN2: =IFERROR(__xludf.DUMMYFUNCTION("SPARKLINE(BN$3,{""charttype"",""column"";""ymin"",MIN($U$3:$BD$3);""ymax"",MAX($U$3:$BD$3);""color"",""blue""})"),"") | BO2: =IFERROR(__xludf.DUMMYFUNCTION("SPARKLINE(BO$3,{""charttype"",""column"";""ymin"",MIN($U$3:$BD$3);""ymax"",MAX($U$3:$BD$3);""color"",""blue""})"),"") | BP2: =IFERROR(__xludf.DUMMYFUNCTION("SPARKLINE(BP$3,{""charttype"",""column"";""ymin"",MIN($U$3:$BD$3);""ymax"",MAX($U$3:$BD$3);""color"",""blue""})"),"") | BQ2: =IFERROR(__xludf.DUMMYFUNCTION("SPARKLINE(BQ$3,{""charttype"",""column"";""ymin"",MIN($U$3:$BD$3);""ymax"",MAX($U$3:$BD$3);""color"",""blue""})"),"") | BR2: =IFERROR(__xludf.DUMMYFUNCTION("SPARKLINE(BR$3,{""charttype"",""column"";""ymin"",MIN($U$3:$BD$3);""ymax"",MAX($U$3:$BD$3);""color"",""blue""})"),"")
A3: =COUNTA(B6:B1506) -> 140 | B3: ออกใบเสนอราคาแล้ว | U3: =SUMPRODUCT($Q$6:$Q1506,U6:U1506) -> 32 | V3: =SUMPRODUCT($Q$6:$Q1506,V6:V1506) -> 32 | W3: =SUMPRODUCT($Q$6:$Q1506,W6:W1506) -> 2 | X3: =SUMPRODUCT($Q$6:$Q1506,X6:X1506) -> 30 | Y3: =SUMPRODUCT($Q$6:$Q1506,Y6:Y1506) -> 13 | Z3: =SUMPRODUCT($Q$6:$Q1506,Z6:Z1506) -> 32 | AA3: =SUMPRODUCT($Q$6:$Q1506,AA6:AA1506) -> 0 | AB3: =SUMPRODUCT($Q$6:$Q1506,AB6:AB1506) -> 0 | ... BR3: =SUMPRODUCT($Q$6:$Q1506,BR6:BR1506) -> 0
E4: โหลด | F4: ขนย้าย | G4: ติดต้ั้ง | H4: โกดัง | I4: ทำของ | J4: มาร์กไลน์ | K4: อื่นๆ | U4: {=INDEX(List_Nickname,U$5)} -> ตี๋ | V4: {=INDEX(List_Nickname,V$5)} -> พี่หนู / ชาย | W4: {=INDEX(List_Nickname,W$5)} -> พี่ล้าน | X4: {=INDEX(List_Nickname,X$5)} -> พี่บอล | Y4: {=INDEX(List_Nickname,Y$5)} -> พี่เดี่ยว | Z4: {=INDEX(List_Nickname,Z$5)} -> พี่ตุ๊ก | AA4: {=INDEX(List_Nickname,AA$5)} -> แพร | AB4: {=INDEX(List_Nickname,AB$5)} -> พี่เปิ้ล | ... BR4: {=INDEX(List_Nickname,BR$5)}
A5: ID | B5: QT | C5: ชื่องาน | D5: ชื่องานย่อย | L5: อธิบายงาน | M5: วันที่เริ่ม | N5: เวลาเริ่ม | O5: วันที่เลิก | P5: เวลาเลิก | Q5: ชั่วโมงทำงาน | R5: จำนวนคนที่ต้องการ | S5: ปริมาณงาน | T5: จำนวนคนที่ได้ | U5: 1 | V5: 2 | W5: 3 | X5: 4 | Y5: 5 | Z5: 6 | AA5: 7 | AB5: 8 | AC5: 9 | AD5: 10 | AE5: 11 | AF5: 12 | AG5: 13 | AH5: 14 | AI5: 15 | AJ5: 16 | AK5: 17 | AL5: 18 | AM5: 19 | AN5: 20 | AO5: 21 | AP5: 22 | AQ5: 23 | AR5: 24 | AS5: 25 | AT5: 26 | AU5: 27 | AV5: 28 | AW5: 29 | AX5: 30 | AY5: 31 | AZ5: 32 | BA5: 33 | BB5: 34 | BC5: 35 | BD5: 36 | BE5: 37 | BF5: 38 | BG5: 39 | BH5: 40 | BI5: 41 | BJ5: 42 | BK5: 43 | BL5: 44 | BM5: 45 | BN5: 46 | BO5: 47 | BP5: 48 | BQ5: 49 | BR5: 50
A6: {=SEQUENCE(1000,1)} -> 1 | B6: QT2025080042 | C6: บริษัทร้อกเวิธ | D6: TOYOTA บางบ่อHO3/HO2 | G6: 1 | L6: ติดตั้งชุดโต๊ะทำงาน | M6: 46078 | N6: 0.29166667 | O6: 46078 | P6: 0.375 | Q6: =IFERROR((DATEVALUE(O6)+TIMEVALUE(P6)-DATEVALUE(M6)-TIMEVALUE(N6))*24,) -> 2 | R6: 5 | S6: =Q6*T6 -> 14 | T6: =countif(U6:BR6,"="&1) -> 7 | U6: 1 | V6: 1 | W6: 1 | Y6: 1 | Z6: 1 | AC6: 1 | AV6: 1
A7: 2 | B7: QT2025080042 | C7: บริษัทร้อกเวิธ | D7: TOYOTA บางบ่อHO2 | E7: 1 | L7: โหลดตู้ Locker | M7: 46078 | N7: 0.375 | O7: 46078 | P7: 0.70833333 | Q7: =IFERROR((DATEVALUE(O7)+TIMEVALUE(P7)-DATEVALUE(M7)-TIMEVALUE(N7))*24,) -> 8 | S7: =Q7*T7 -> 24 | T7: =countif(U7:BR7,"="&1) -> 3 | AD7: 1 | AE7: 1 | AS7: 1
A8: 3 | B8: QT2025080042 | C8: บริษัทร้อกเวิธ | D8: TOYOTA บ้านโพธิ์ | G8: 1 | L8: ติดตั้ง | M8: 46078 | N8: 0.66666667 | O8: 46079 | P8: 0.125 | Q8: =IFERROR((DATEVALUE(O8)+TIMEVALUE(P8)-DATEVALUE(M8)-TIMEVALUE(N8))*24,) -> 11 | R8: 2 | S8: =Q8*T8 -> 44 | T8: =countif(U8:BR8,"="&1) -> 4 | Y8: 1 | AD8: 1 | AG8: 1 | AS8: 1
A9: 4 | B9: QT2025090063 | C9: บริษัทโอคามูระ | D9: TOYOTA บางบ่อ HO2 | K9: 1 | L9: ส่งเก้าอี้ เก้าอี้โต๊ะประชุม8 / เก้าอี้ทำงาน 162 / EVP-พาทิชั่น 2 | M9: 46078 | O9: 46078 | T9: =countif(U9:BR9,"="&1) -> 3 | X9: 1 | AG9: 1 | AJ9: 1
A10: 5 | B10: QT2025120083-QT2026020053 | C10: บริษัทร้อกเวิธ | D10: Space Matrix Design / PJ. Galderma Thailand | G10: 1 | L10: ต้องจบงาน! | M10: 46078 | O10: 46078 | Q10: =IFERROR((DATEVALUE(O10)+TIMEVALUE(P10)-DATEVALUE(M10)-TIMEVALUE(N10))*24,) | S10: =Q10*T10 -> 0 | T10: =countif(U10:BR10,"="&1) -> 6 | AK10: 1 | AM10: 1 | AN10: 1 | AR10: 1 | AU10: 1 | AW10: 1
A11: 6 | C11: บริษัทโอคามูระ | D11: GSK One ดุสิต ชั้น 25 | J11: 1 | L11: มาร์กไลน์ | M11: 46078 | O11: 46078 | Q11: =IFERROR((DATEVALUE(O11)+TIMEVALUE(P11)-DATEVALUE(M11)-TIMEVALUE(N11))*24,) | S11: =Q11*T11 -> 0 | T11: =countif(U11:BR11,"="&1) -> 1 | AQ11: 1
A12: 7 | B12: QT2026010080 | C12: บริษัทร้อกเวิธ | D12: บริษัท เงินทุนแอร์ดวาน | K12: 1 | L12: ส่งเก้าอี้ที่ร้านเบาะกิติธร | M12: 46078 | N12: 0.75 | O12: 46078 | P12: 0.041666667 | Q12: =IFERROR((DATEVALUE(O12)+TIMEVALUE(P12)-DATEVALUE(M12)-TIMEVALUE(N12))*24,) -> -17 | S12: =Q12*T12 -> -17 | T12: =countif(U12:BR12,"="&1) -> 1 | AQ12: 1
A13: 8 | C13: บริษัทร้อกเวิธ | D13: TOYOTA AUTO | J13: 1 | L13: มาร์กไลน์ | M13: 46079 | N13: 0.375 | O13: 46079 | P13: 0.70833333 | Q13: =IFERROR((DATEVALUE(O13)+TIMEVALUE(P13)-DATEVALUE(M13)-TIMEVALUE(N13))*24,) -> 8 | S13: =Q13*T13 -> 0 | T13: =countif(U13:BR13,"="&1) -> 0
A14: 9 | B14: QT2026020004 | C14: บริษัทโอคามูระ | D14: เดลีเทค อาคารThr Parq พระราม4 | E14: 1 | L14: จัมโบ้+กะบะ (รับของปู่เจ้า14.00 ส่งหน้างานได้หลัง18.00น. ) | M14: 46078 | O14: 46078 | Q14: =IFERROR((DATEVALUE(O14)+TIMEVALUE(P14)-DATEVALUE(M14)-TIMEVALUE(N14))*24,) | S14: =Q14*T14 -> 0 | T14: =countif(U14:BR14,"="&1) -> 7 | AK14: 1 | AM14: 1 | AN14: 1 | AQ14: 1 | AR14: 1 | AU14: 1 | AW14: 1
A15: 10 | B15: QT2025070009 | C15: บริษัทร้อกเวิธ | D15: การบินไทย Phas1 อาคาร 5 ชั้น 18 | K15: 1 | L15: ส่งงานกับทางการบิน | M15: 46078 | N15: 0.75 | O15: 46078 | P15: 0.875 | Q15: =IFERROR((DATEVALUE(O15)+TIMEVALUE(P15)-DATEVALUE(M15)-TIMEVALUE(N15))*24,) -> 3 | S15: =Q15*T15 -> 9 | T15: =countif(U15:BR15,"="&1) -> 3 | AF15: 1 | AX15: 1 | AZ15: 1
A16: 11 | C16: บริษัทร้อกเวิธ | D16: RW วางบิล | K16: 1 | L16: วางบิลก่อนเที่ยง | M16: 46078 | O16: 46078 | Q16: =IFERROR((DATEVALUE(O16)+TIMEVALUE(P16)-DATEVALUE(M16)-TIMEVALUE(N16))*24,) | S16: =Q16*T16 -> 0 | T16: =countif(U16:BR16,"="&1) -> 1 | AX16: 1
A17: 12 | C17: บริษัทโอคามูระ | D17: โอคามูระ | K17: 1 | L17: รับเช็คโอคามูระ 14.00-16.00 น. | M17: 46078 | N17: 0.375 | O17: 46078 | P17: 0.5 | Q17: =IFERROR((DATEVALUE(O17)+TIMEVALUE(P17)-DATEVALUE(M17)-TIMEVALUE(N17))*24,) -> 3 | S17: =Q17*T17 -> 3 | T17: =countif(U17:BR17,"="&1) -> 1 | AX17: 1
A18: 13 | B18: QT2025080042 | C18: บริษัทร้อกเวิธ | D18: TOYOTA บางบ่อHO2 | G18: 1 | L18: ติดตั้งชุดโต๊ะทำงาน | M18: 46079 | N18: 0.29166667 | O18: 46079 | P18: 0.83333333 | Q18: =IFERROR((DATEVALUE(O18)+TIMEVALUE(P18)-DATEVALUE(M18)-TIMEVALUE(N18))*24,) -> 13 | S18: =Q18*T18 -> 91 | T18: =countif(U18:BR18,"="&1) -> 7 | U18: 1 | V18: 1 | X18: 1 | Z18: 1 | AJ18: 1 | AS18: 1 | AV18: 1
A19: 14 | B19: QT2025080042 | C19: บริษัทร้อกเวิธ | D19: TOYOTA บางบ่อHO1 | E19: 1 | L19: โหลดตู้ Locker | M19: 46079 | N19: 0.375 | O19: 46079 | P19: 0.5 | Q19: =IFERROR((DATEVALUE(O19)+TIMEVALUE(P19)-DATEVALUE(M19)-TIMEVALUE(N19))*24,) -> 3 | S19: =Q19*T19 -> 6 | T19: =countif(U19:BR19,"="&1) -> 2 | AE19: 1 | BB19: 1
A20: 15 | B20: QT2025080042 | C20: บริษัทร้อกเวิธ | D20: TOYOTA บ้านโพธิ์ | G20: 1 | L20: ติดตั้ง | M20: 46079 | O20: 46079 | Q20: =IFERROR((DATEVALUE(O20)+TIMEVALUE(P20)-DATEVALUE(M20)-TIMEVALUE(N20))*24,) | S20: =Q20*T20 -> 0 | T20: =countif(U20:BR20,"="&1) -> 7 | Y20: 1 | AD20: 1 | AG20: 1 | AQ20: 1 | AR20: 1 | AW20: 1 | AY20: 1
A21: 16 | B21: QT2025070009 | C21: บริษัทร้อกเวิธ | D21: การบินไทย Phas1 อาคาร 5 ชั้น 7 | F21: 1 | L21: ขนย้ายเฟอร์นิเจอร์-จัดสำนักงาน | M21: 46081 | O21: 46081 | Q21: =IFERROR((DATEVALUE(O21)+TIMEVALUE(P21)-DATEVALUE(M21)-TIMEVALUE(N21))*24,) | S21: =Q21*T21 -> 0 | T21: =countif(U21:BR21,"="&1) -> 1 | AF21: 1
A22: 17 | B22: QT2026020038 | C22: บริษัทร้อกเวิธ | D22: บริษัท สตูดิโอ | F22: 1 | L22: รื้อแพ็ค | M22: 46079 | O22: 46079 | Q22: =IFERROR((DATEVALUE(O22)+TIMEVALUE(P22)-DATEVALUE(M22)-TIMEVALUE(N22))*24,) | S22: =Q22*T22 -> 0 | T22: =countif(U22:BR22,"="&1) -> 4 | AK22: 1 | AM22: 1 | AN22: 1 | AU22: 1
A23: 18 | B23: QT2026020004 | C23: บริษัทโอคามูระ | D23: เลดีเทค โหลด Thr Parq พระราม4 | G23: 1 | L23: ติดตั้ง | M23: 46079 | O23: 46079 | Q23: =IFERROR((DATEVALUE(O23)+TIMEVALUE(P23)-DATEVALUE(M23)-TIMEVALUE(N23))*24,) | S23: =Q23*T23 -> 0 | T23: =countif(U23:BR23,"="&1) -> 7 | AK23: 1 | AM23: 1 | AN23: 1 | AQ23: 1 | AR23: 1 | AU23: 1 | AW23: 1
A24: 19 | B24: QT2025080042 | C24: บริษัทร้อกเวิธ | D24: TOYOTA บางบ่อHO3/HO2 | G24: 1 | L24: ติดตั้ง | M24: 46080 | N24: 0.375 | O24: 46080 | P24: 0.875 | Q24: =IFERROR((DATEVALUE(O24)+TIMEVALUE(P24)-DATEVALUE(M24)-TIMEVALUE(N24))*24,) -> 12 | S24: =Q24*T24 -> 84 | T24: =countif(U24:BR24,"="&1) -> 7 | U24: 1 | V24: 1 | X24: 1 | Z24: 1 | AJ24: 1 | AS24: 1 | AV24: 1
A25: 20 | B25: QT2025080042 | C25: บริษัทร้อกเวิธ | D25: TOYOTA บ้านโพธิ์ | G25: 1 | L25: ติดตั้ง | M25: 46080 | O25: 46080 | Q25: =IFERROR((DATEVALUE(O25)+TIMEVALUE(P25)-DATEVALUE(M25)-TIMEVALUE(N25))*24,) | S25: =Q25*T25 -> 0 | T25: =countif(U25:BR25,"="&1) -> 6 | Y25: 1 | AG25: 1 | AQ25: 1 | AR25: 1 | AW25: 1 | AY25: 1
A26: 21 | B26: QT2026020038 | C26: บริษัทร้อกเวิธ | D26: บริษัท สตูดิโอ | F26: 1 | L26: รื้อแแพ็ค | M26: 46080 | O26: 46080 | Q26: =IFERROR((DATEVALUE(O26)+TIMEVALUE(P26)-DATEVALUE(M26)-TIMEVALUE(N26))*24,) | S26: =Q26*T26 -> 0 | T26: =countif(U26:BR26,"="&1) -> 0
A27: 22 | B27: QT2025070009 | C27: บริษัทร้อกเวิธ | D27: การบินไทย Phas1 อาคาร 5 ชั้น 7 | F27: 1 | L27: ขนย้าย | M27: 46080 | O27: 46080 | Q27: =IFERROR((DATEVALUE(O27)+TIMEVALUE(P27)-DATEVALUE(M27)-TIMEVALUE(N27))*24,) | S27: =Q27*T27 -> 0 | T27: =countif(U27:BR27,"="&1) -> 1 | AF27: 1
A28: 23 | B28: QT2026020006 | C28: บริษัทโอคามูระ | D28: โปรเจค HA | E28: 1 | G28: 1 | L28: ขนส่ง-โหลด-ติดตั้ง | M28: 46080 | O28: 46080 | Q28: =IFERROR((DATEVALUE(O28)+TIMEVALUE(P28)-DATEVALUE(M28)-TIMEVALUE(N28))*24,) | S28: =Q28*T28 -> 0 | T28: =countif(U28:BR28,"="&1) -> 0
A29: 24 | B29: QT2025080042 | C29: บริษัทร้อกเวิธ | D29: TOYOTA บางบ่อHO3/HO2 | G29: 1 | L29: ติดตั้ง | M29: 46081 | N29: 0.75 | O29: 46081 | P29: 0.95833333 | Q29: =IFERROR((DATEVALUE(O29)+TIMEVALUE(P29)-DATEVALUE(M29)-TIMEVALUE(N29))*24,) -> 5 | S29: =Q29*T29 -> 35 | T29: =countif(U29:BR29,"="&1) -> 7 | U29: 1 | V29: 1 | X29: 1 | Z29: 1 | AJ29: 1 | AS29: 1 | AV29: 1
A30: 25 | B30: QT2025080042 | C30: บริษัทร้อกเวิธ | D30: TOYOTA บ้านโพธิ์ | G30: 1 | L30: ติดตั้ง | M30: 46081 | O30: 46081 | Q30: =IFERROR((DATEVALUE(O30)+TIMEVALUE(P30)-DATEVALUE(M30)-TIMEVALUE(N30))*24,) | S30: =Q30*T30 -> 0 | T30: =countif(U30:BR30,"="&1) -> 7 | AD30: 1 | AE30: 1 | AG30: 1 | AQ30: 1 | AR30: 1 | AW30: 1 | AY30: 1
A31: 26 | B31: QT2026010096 | C31: บริษัทร้อกเวิธ | D31: โหลด ธนชาติ | E31: 1 | G31: 1 | L31: โหลดตู้ Phone Booth จำนวน 4 ตู้ (โหลด+ประกอบบ่างส่วน) | M31: 46081 | O31: 46081 | Q31: =IFERROR((DATEVALUE(O31)+TIMEVALUE(P31)-DATEVALUE(M31)-TIMEVALUE(N31))*24,) | S31: =Q31*T31 -> 0 | T31: =countif(U31:BR31,"="&1) -> 4 | X31: 1 | AE31: 1 | AJ31: 1 | BB31: 1
A32: 27 | B32: QT2025070009 | C32: บริษัทร้อกเวิธ | D32: การบินไทย Phas1 อาคาร 5 ชั้น 7 | F32: 1 | L32: ขนย้ายเฟอร์นิเจอร์-จัดสำนักงาน | M32: 46081 | O32: 46081 | Q32: =IFERROR((DATEVALUE(O32)+TIMEVALUE(P32)-DATEVALUE(M32)-TIMEVALUE(N32))*24,) | S32: =Q32*T32 -> 0 | T32: =countif(U32:BR32,"="&1) -> 1 | AF32: 1
A33: 28 | C33: บริษัทพาส 409 | D33: พาส409-Exxon | F33: 1 | L33: รื้อตู้ล็อกเกอร์ 1 ใบที่ชั้น15 มาสลับกับชั้น6 | M33: 46081 | O33: 46081 | Q33: =IFERROR((DATEVALUE(O33)+TIMEVALUE(P33)-DATEVALUE(M33)-TIMEVALUE(N33))*24,) | S33: =Q33*T33 -> 0 | T33: =countif(U33:BR33,"="&1) -> 3 | V33: 1 | X33: 1 | AJ33: 1
A34: 29 | B34: QT2026010060 | C34: เคมัว | D34: เค มัวร์ | K34: 1 | L34: รื้อ ขนทื้ง | M34: 46081 | O34: 46081 | Q34: =IFERROR((DATEVALUE(O34)+TIMEVALUE(P34)-DATEVALUE(M34)-TIMEVALUE(N34))*24,) | S34: =Q34*T34 -> 0 | T34: =countif(U34:BR34,"="&1) -> 0
A35: 30 | C35: บริษัทร้อกเวิธ | D35: A1-RW UOB ย้ายตู้ Mail Box 2 ใบ | F35: 1 | L35: ย้ายตู้ Mail Box 2 ใบ | M35: 46081 | O35: 46081 | Q35: =IFERROR((DATEVALUE(O35)+TIMEVALUE(P35)-DATEVALUE(M35)-TIMEVALUE(N35))*24,) | S35: =Q35*T35 -> 0 | T35: =countif(U35:BR35,"="&1) -> 0
A36: 31 | C36: บริษัทร้อกเวิธ | D36: การบินไทย Phas1 อาคาร 5 ชั้น 18 | F36: 1 | L36: ส่งงาน | M36: 46079 | O36: 46079 | Q36: =IFERROR((DATEVALUE(O36)+TIMEVALUE(P36)-DATEVALUE(M36)-TIMEVALUE(N36))*24,) | S36: =Q36*T36 -> 0 | T36: =countif(U36:BR36,"="&1) -> 0
A37: 32 | Q37: =IFERROR((DATEVALUE(O37)+TIMEVALUE(P37)-DATEVALUE(M37)-TIMEVALUE(N37))*24,) | S37: =Q37*T37 -> 0 | T37: =countif(U37:BR37,"="&1) -> 0
A38: 33 | Q38: =IFERROR((DATEVALUE(O38)+TIMEVALUE(P38)-DATEVALUE(M38)-TIMEVALUE(N38))*24,) | S38: =Q38*T38 -> 0 | T38: =countif(U38:BR38,"="&1) -> 0
A39: 34 | Q39: =IFERROR((DATEVALUE(O39)+TIMEVALUE(P39)-DATEVALUE(M39)-TIMEVALUE(N39))*24,) | S39: =Q39*T39 -> 0 | T39: =countif(U39:BR39,"="&1) -> 0
A40: 35 | Q40: =IFERROR((DATEVALUE(O40)+TIMEVALUE(P40)-DATEVALUE(M40)-TIMEVALUE(N40))*24,) | S40: =Q40*T40 -> 0 | T40: =countif(U40:BR40,"="&1) -> 0
...

Sheet ViewByMonth
A1: 1 | B1: 2 | C1: 3 | D1: 4 | E1: 5 | F1: 6 | G1: 7 | H1: 8 | I1: 9 | J1: 10 | K1: 11 | L1: 12 | M1: 13 | N1: 14 | O1: 15 | P1: 16 | Q1: 17 | R1: 18 | S1: 19 | T1: 20 | U1: 21 | V1: 22 | W1: 23 | X1: 24 | Y1: 25 | Z1: 26 | AA1: 27 | AB1: 28 | AC1: 29 | AD1: 30 | AE1: 31 | AF1: 32 | AG1: 33 | AH1: 34 | AI1: 35 | AJ1: 36 | AK1: 37 | AL1: 38 | AM1: 39 | AN1: 40 | AO1: 41 | AP1: 42 | AQ1: 43 | AR1: 44 | AS1: 45 | AT1: 46 | AU1: 47 | AV1: 48 | AW1: 49 | AX1: 50 | AY1: 51 | AZ1: 52 | BA1: 53 | BB1: 54 | BC1: 55 | BD1: 56 | BE1: 57 | BF1: 58 | BG1: 59 | BH1: 60 | BI1: 61 | BJ1: 62 | BK1: 63 | BL1: 64 | BM1: 65 | BN1: 66 | BO1: 67 | BP1: 68 | BQ1: 69 | BR1: 70 | BS1: 71 | BT1: 72 | BU1: 73 | BV1: 74 | BW1: 75 | BX1: 76 | BY1: 77 | BZ1: 78 | CA1: 79 | CB1: 80 | CC1: 81 | CD1: 82 | CE1: 83 | CF1: 84 | CG1: 85 | CH1: 86 | CI1: 87 | CJ1: 88 | CK1: 89 | CL1: 90 | CM1: 91 | CN1: 92
C2: 2026 | BT2: =COLUMN(BT2) -> 72
C3: กุมภาพันธ์ | S3: ปริมาณงานสูงสุดที่ทำได้ | T3: =Parameter!$Q$2*Parameter!$Q$3*Parameter!$Q$4 -> 7072 | V3: =IFERROR(__xludf.DUMMYFUNCTION("SPARKLINE(V$4,{""charttype"",""column"";""ymin"",MIN($V$4:$BE$4);""ymax"",MAX($V$4:$BE$4);""color"",""blue""})"),"") | W3: =IFERROR(__xludf.DUMMYFUNCTION("SPARKLINE(W$4,{""charttype"",""column"";""ymin"",MIN($V$4:$BE$4);""ymax"",MAX($V$4:$BE$4);""color"",""blue""})"),"") | X3: =IFERROR(__xludf.DUMMYFUNCTION("SPARKLINE(X$4,{""charttype"",""column"";""ymin"",MIN($V$4:$BE$4);""ymax"",MAX($V$4:$BE$4);""color"",""blue""})"),"") | Y3: =IFERROR(__xludf.DUMMYFUNCTION("SPARKLINE(Y$4,{""charttype"",""column"";""ymin"",MIN($V$4:$BE$4);""ymax"",MAX($V$4:$BE$4);""color"",""blue""})"),"") | Z3: =IFERROR(__xludf.DUMMYFUNCTION("SPARKLINE(Z$4,{""charttype"",""column"";""ymin"",MIN($V$4:$BE$4);""ymax"",MAX($V$4:$BE$4);""color"",""blue""})"),"") | AA3: =IFERROR(__xludf.DUMMYFUNCTION("SPARKLINE(AA$4,{""charttype"",""column"";""ymin"",MIN($V$4:$BE$4);""ymax"",MAX($V$4:$BE$4);""color"",""blue""})"),"") | AB3: =IFERROR(__xludf.DUMMYFUNCTION("SPARKLINE(AB$4,{""charttype"",""column"";""ymin"",MIN($V$4:$BE$4);""ymax"",MAX($V$4:$BE$4);""color"",""blue""})"),"") | AC3: =IFERROR(__xludf.DUMMYFUNCTION("SPARKLINE(AC$4,{""charttype"",""column"";""ymin"",MIN($V$4:$BE$4);""ymax"",MAX($V$4:$BE$4);""color"",""blue""})"),"") | AD3: =IFERROR(__xludf.DUMMYFUNCTION("SPARKLINE(AD$4,{""charttype"",""column"";""ymin"",MIN($V$4:$BE$4);""ymax"",MAX($V$4:$BE$4);""color"",""blue""})"),"") | AE3: =IFERROR(__xludf.DUMMYFUNCTION("SPARKLINE(AE$4,{""charttype"",""column"";""ymin"",MIN($V$4:$BE$4);""ymax"",MAX($V$4:$BE$4);""color"",""blue""})"),"") | AF3: =IFERROR(__xludf.DUMMYFUNCTION("SPARKLINE(AF$4,{""charttype"",""column"";""ymin"",MIN($V$4:$BE$4);""ymax"",MAX($V$4:$BE$4);""color"",""blue""})"),"") | AG3: =IFERROR(__xludf.DUMMYFUNCTION("SPARKLINE(AG$4,{""charttype"",""column"";""ymin"",MIN($V$4:$BE$4);""ymax"",MAX($V$4:$BE$4);""color"",""blue""})"),"") | AH3: =IFERROR(__xludf.DUMMYFUNCTION("SPARKLINE(AH$4,{""charttype"",""column"";""ymin"",MIN($V$4:$BE$4);""ymax"",MAX($V$4:$BE$4);""color"",""blue""})"),"") | AI3: =IFERROR(__xludf.DUMMYFUNCTION("SPARKLINE(AI$4,{""charttype"",""column"";""ymin"",MIN($V$4:$BE$4);""ymax"",MAX($V$4:$BE$4);""color"",""blue""})"),"") | AJ3: =IFERROR(__xludf.DUMMYFUNCTION("SPARKLINE(AJ$4,{""charttype"",""column"";""ymin"",MIN($V$4:$BE$4);""ymax"",MAX($V$4:$BE$4);""color"",""blue""})"),"") | AK3: =IFERROR(__xludf.DUMMYFUNCTION("SPARKLINE(AK$4,{""charttype"",""column"";""ymin"",MIN($V$4:$BE$4);""ymax"",MAX($V$4:$BE$4);""color"",""blue""})"),"") | AL3: =IFERROR(__xludf.DUMMYFUNCTION("SPARKLINE(AL$4,{""charttype"",""column"";""ymin"",MIN($V$4:$BE$4);""ymax"",MAX($V$4:$BE$4);""color"",""blue""})"),"") | AM3: =IFERROR(__xludf.DUMMYFUNCTION("SPARKLINE(AM$4,{""charttype"",""column"";""ymin"",MIN($V$4:$BE$4);""ymax"",MAX($V$4:$BE$4);""color"",""blue""})"),"") | AN3: =IFERROR(__xludf.DUMMYFUNCTION("SPARKLINE(AN$4,{""charttype"",""column"";""ymin"",MIN($V$4:$BE$4);""ymax"",MAX($V$4:$BE$4);""color"",""blue""})"),"") | AO3: =IFERROR(__xludf.DUMMYFUNCTION("SPARKLINE(AO$4,{""charttype"",""column"";""ymin"",MIN($V$4:$BE$4);""ymax"",MAX($V$4:$BE$4);""color"",""blue""})"),"") | AP3: =IFERROR(__xludf.DUMMYFUNCTION("SPARKLINE(AP$4,{""charttype"",""column"";""ymin"",MIN($V$4:$BE$4);""ymax"",MAX($V$4:$BE$4);""color"",""blue""})"),"") | AQ3: =IFERROR(__xludf.DUMMYFUNCTION("SPARKLINE(AQ$4,{""charttype"",""column"";""ymin"",MIN($V$4:$BE$4);""ymax"",MAX($V$4:$BE$4);""color"",""blue""})"),"") | AR3: =IFERROR(__xludf.DUMMYFUNCTION("SPARKLINE(AR$4,{""charttype"",""column"";""ymin"",MIN($V$4:$BE$4);""ymax"",MAX($V$4:$BE$4);""color"",""blue""})"),"") | AS3: =IFERROR(__xludf.DUMMYFUNCTION("SPARKLINE(AS$4,{""charttype"",""column"";""ymin"",MIN($V$4:$BE$4);""ymax"",MAX($V$4:$BE$4);""color"",""blue""})"),"") | AT3: =IFERROR(__xludf.DUMMYFUNCTION("SPARKLINE(AT$4,{""charttype"",""column"";""ymin"",MIN($V$4:$BE$4);""ymax"",MAX($V$4:$BE$4);""color"",""blue""})"),"") | AU3: =IFERROR(__xludf.DUMMYFUNCTION("SPARKLINE(AU$4,{""charttype"",""column"";""ymin"",MIN($V$4:$BE$4);""ymax"",MAX($V$4:$BE$4);""color"",""blue""})"),"") | AV3: =IFERROR(__xludf.DUMMYFUNCTION("SPARKLINE(AV$4,{""charttype"",""column"";""ymin"",MIN($V$4:$BE$4);""ymax"",MAX($V$4:$BE$4);""color"",""blue""})"),"") | AW3: =IFERROR(__xludf.DUMMYFUNCTION("SPARKLINE(AW$4,{""charttype"",""column"";""ymin"",MIN($V$4:$BE$4);""ymax"",MAX($V$4:$BE$4);""color"",""blue""})"),"") | AX3: =IFERROR(__xludf.DUMMYFUNCTION("SPARKLINE(AX$4,{""charttype"",""column"";""ymin"",MIN($V$4:$BE$4);""ymax"",MAX($V$4:$BE$4);""color"",""blue""})"),"") | AY3: =IFERROR(__xludf.DUMMYFUNCTION("SPARKLINE(AY$4,{""charttype"",""column"";""ymin"",MIN($V$4:$BE$4);""ymax"",MAX($V$4:$BE$4);""color"",""blue""})"),"") | AZ3: =IFERROR(__xludf.DUMMYFUNCTION("SPARKLINE(AZ$4,{""charttype"",""column"";""ymin"",MIN($V$4:$BE$4);""ymax"",MAX($V$4:$BE$4);""color"",""blue""})"),"") | BA3: =IFERROR(__xludf.DUMMYFUNCTION("SPARKLINE(BA$4,{""charttype"",""column"";""ymin"",MIN($V$4:$BE$4);""ymax"",MAX($V$4:$BE$4);""color"",""blue""})"),"") | BB3: =IFERROR(__xludf.DUMMYFUNCTION("SPARKLINE(BB$4,{""charttype"",""column"";""ymin"",MIN($V$4:$BE$4);""ymax"",MAX($V$4:$BE$4);""color"",""blue""})"),"") | BC3: =IFERROR(__xludf.DUMMYFUNCTION("SPARKLINE(BC$4,{""charttype"",""column"";""ymin"",MIN($V$4:$BE$4);""ymax"",MAX($V$4:$BE$4);""color"",""blue""})"),"") | BD3: =IFERROR(__xludf.DUMMYFUNCTION("SPARKLINE(BD$4,{""charttype"",""column"";""ymin"",MIN($V$4:$BE$4);""ymax"",MAX($V$4:$BE$4);""color"",""blue""})"),"") | BE3: =IFERROR(__xludf.DUMMYFUNCTION("SPARKLINE(BE$4,{""charttype"",""column"";""ymin"",MIN($V$4:$BE$4);""ymax"",MAX($V$4:$BE$4);""color"",""blue""})"),"") | BF3: =IFERROR(__xludf.DUMMYFUNCTION("SPARKLINE(BF$4,{""charttype"",""column"";""ymin"",MIN($V$4:$BE$4);""ymax"",MAX($V$4:$BE$4);""color"",""blue""})"),"") | BG3: =IFERROR(__xludf.DUMMYFUNCTION("SPARKLINE(BG$4,{""charttype"",""column"";""ymin"",MIN($V$4:$BE$4);""ymax"",MAX($V$4:$BE$4);""color"",""blue""})"),"") | BH3: =IFERROR(__xludf.DUMMYFUNCTION("SPARKLINE(BH$4,{""charttype"",""column"";""ymin"",MIN($V$4:$BE$4);""ymax"",MAX($V$4:$BE$4);""color"",""blue""})"),"") | BI3: =IFERROR(__xludf.DUMMYFUNCTION("SPARKLINE(BI$4,{""charttype"",""column"";""ymin"",MIN($V$4:$BE$4);""ymax"",MAX($V$4:$BE$4);""color"",""blue""})"),"")
S4: ปริมาณงานที่ทำ | T4: =SUM(T7:T1004) -> 293 | V4: =SUMPRODUCT($R$7:$R1004,V7:V1004) -> 32 | W4: =SUMPRODUCT($R$7:$R1004,W7:W1004) -> 32 | X4: =SUMPRODUCT($R$7:$R1004,X7:X1004) -> 2 | Y4: =SUMPRODUCT($R$7:$R1004,Y7:Y1004) -> 30 | Z4: =SUMPRODUCT($R$7:$R1004,Z7:Z1004) -> 13 | AA4: =SUMPRODUCT($R$7:$R1004,AA7:AA1004) -> 32 | AB4: =SUMPRODUCT($R$7:$R1004,AB7:AB1004) -> 0 | AC4: =SUMPRODUCT($R$7:$R1004,AC7:AC1004) -> 0 | ... BI4: =SUMPRODUCT($R$7:$R1004,BI7:BI1004) -> 0
B5: =COUNTA(B7:B1004) -> 31 | F5: โหลด | G5: ขนย้าย | H5: ติดต้ั้ง | I5: โกดัง | J5: ทำของ | K5: มาร์กไลน์ | L5: อื่นๆ | N5: =TODAY() -> 46078 | S5: อัตรางานที่ที่ทำ | T5: =T4/T3 -> 0.041430995 | V5: {=INDEX(List_Nickname,V$6)} -> ตี๋ | W5: {=INDEX(List_Nickname,W$6)} -> พี่หนู / ชาย | X5: {=INDEX(List_Nickname,X$6)} -> พี่ล้าน | Y5: {=INDEX(List_Nickname,Y$6)} -> พี่บอล | Z5: {=INDEX(List_Nickname,Z$6)} -> พี่เดี่ยว | AA5: {=INDEX(List_Nickname,AA$6)} -> พี่ตุ๊ก | AB5: {=INDEX(List_Nickname,AB$6)} -> แพร | AC5: {=INDEX(List_Nickname,AC$6)} -> พี่เปิ้ล | ... BS5: {=INDEX(List_Nickname,BS$6)} | CG5: ล่วงเวลาวันปกติ | CH5: เวลาปกติ วันหยุด | CI5: ล่วงเวลาวันหยุด
A6: ลำดับ | B6: ID | C6: QT | D6: ชื่องาน | E6: ชื่องานย่อย | M6: อธิบายงาน | N6: วันที่เริ่ม | O6: เวลาเริ่ม | P6: วันที่เลิก | Q6: เวลาเลิก | R6: ชั่วโมงทำงาน | S6: จำนวนคนที่ต้องการ | T6: ปริมาณงาน | U6: จำนวนคนที่ได้ | V6: 1 | W6: 2 | X6: 3 | Y6: 4 | Z6: 5 | AA6: 6 | AB6: 7 | AC6: 8 | AD6: 9 | AE6: 10 | AF6: 11 | AG6: 12 | AH6: 13 | AI6: 14 | AJ6: 15 | AK6: 16 | AL6: 17 | AM6: 18 | AN6: 19 | AO6: 20 | AP6: 21 | AQ6: 22 | AR6: 23 | AS6: 24 | AT6: 25 | AU6: 26 | AV6: 27 | AW6: 28 | AX6: 29 | AY6: 30 | AZ6: 31 | BA6: 32 | BB6: 33 | BC6: 34 | BD6: 35 | BE6: 36 | BF6: 37 | BG6: 38 | BH6: 39 | BI6: 40 | BJ6: 41 | BK6: 42 | BL6: 43 | BM6: 44 | BN6: 45 | BO6: 46 | BP6: 47 | BQ6: 48 | BR6: 49 | BS6: 50 | BT6: ชนิดวัน | BU6: Work Start | BV6: Work End | BW6: Lunch Start | BX6: Lunch End | BY6: Dinner Start | BZ6: Dinner End | CA6: Lunch Included | CB6: Dinner Included | CC6: Net Duration | CD6: 0.75 | CE6: Duration Before 6pm | CF6: Duration After 6pm | CG6: OT วันปกติ 1.5 | CH6: OT วันหยุด 2 | CI6: OT หลัง 6pm วันหยุด 3
A7: =IF(ISBLANK(B7),,ROW(A7)-ROW($A$6)) -> 1 | B7: =IFERROR(__xludf.DUMMYFUNCTION("FILTER(dataJobIn,IF($C$2="""",JobDate<>"""",IF($C$3="""",YEAR(JobDate)=vYearSelected,IF($C$4="""",MONTH(JobDate)=vMonthSelected,JobDate=vDateSelected))))"),1.0) -> 1 | C7: =IFERROR(__xludf.DUMMYFUNCTION("""COMPUTED_VALUE"""),"QT2025080042") -> QT2025080042 | D7: =IFERROR(__xludf.DUMMYFUNCTION("""COMPUTED_VALUE"""),"บริษัทร้อกเวิธ") -> บริษัทร้อกเวิธ | E7: =IFERROR(__xludf.DUMMYFUNCTION("""COMPUTED_VALUE"""),"TOYOTA บางบ่อHO3/HO2") -> TOYOTA บางบ่อHO3/HO2 | H7: =IFERROR(__xludf.DUMMYFUNCTION("""COMPUTED_VALUE"""),1.0) -> 1 | M7: =IFERROR(__xludf.DUMMYFUNCTION("""COMPUTED_VALUE"""),"ติดตั้งชุดโต๊ะทำงาน") -> ติดตั้งชุดโต๊ะทำงาน | N7: =IFERROR(__xludf.DUMMYFUNCTION("""COMPUTED_VALUE"""),46078.0) -> 46078 | O7: =IFERROR(__xludf.DUMMYFUNCTION("""COMPUTED_VALUE"""),0.2916666666666667) -> 0.29166667 | P7: =IFERROR(__xludf.DUMMYFUNCTION("""COMPUTED_VALUE"""),46078.0) -> 46078 | Q7: =IFERROR(__xludf.DUMMYFUNCTION("""COMPUTED_VALUE"""),0.375) -> 0.375 | R7: =IFERROR(__xludf.DUMMYFUNCTION("""COMPUTED_VALUE"""),1.9999999999999996) -> 2 | S7: =IFERROR(__xludf.DUMMYFUNCTION("""COMPUTED_VALUE"""),5.0) -> 5 | T7: =IFERROR(__xludf.DUMMYFUNCTION("""COMPUTED_VALUE"""),13.999999999999996) -> 14 | U7: =IFERROR(__xludf.DUMMYFUNCTION("""COMPUTED_VALUE"""),7.0) -> 7 | V7: =IFERROR(__xludf.DUMMYFUNCTION("""COMPUTED_VALUE"""),1.0) -> 1 | W7: =IFERROR(__xludf.DUMMYFUNCTION("""COMPUTED_VALUE"""),1.0) -> 1 | X7: =IFERROR(__xludf.DUMMYFUNCTION("""COMPUTED_VALUE"""),1.0) -> 1 | Z7: =IFERROR(__xludf.DUMMYFUNCTION("""COMPUTED_VALUE"""),1.0) -> 1 | AA7: =IFERROR(__xludf.DUMMYFUNCTION("""COMPUTED_VALUE"""),1.0) -> 1 | AD7: =IFERROR(__xludf.DUMMYFUNCTION("""COMPUTED_VALUE"""),1.0) -> 1 | AW7: =IFERROR(__xludf.DUMMYFUNCTION("""COMPUTED_VALUE"""),1.0) -> 1 | BT7: =IF(ISBLANK(B7),,IF(IFNA(MATCH(N7,List_Holidays,0),0)=0,IF(IFNA(MATCH(WEEKDAY(N7),List_WeekHolidays,0),0),1,0),2)) -> 0 | BU7: =N7+O7 -> 46078.292 | BV7: =P7+Q7 -> 46078.375 | BW7: =IF($BU7>cLunchEnd+$N7,cLunchBegin+$N7+1,cLunchBegin+$N7) -> 46078.5 | BX7: =IF($BU7>cLunchEnd+$N7,cLunchEnd+$N7+1,cLunchEnd+$N7) -> 46078.542 | BY7: =IF($BU7>cDinnerEnd+$N7,cDinnerBegin+$N7+1,cDinnerBegin+$N7) -> 46078.75 | BZ7: =IF($BU7>cDinnerEnd+$N7,cDinnerEnd+$N7+1,cDinnerEnd+$N7) -> 46078.792 | CA7: =IF((MIN($BV7,BX7)-MAX($BU7,BW7))>0,vDurationLunch,) | CB7: =IF((MIN($BV7,BZ7)-MAX($BU7,BY7))>0,vDurationDinner,) | CC7: =(BV7-BU7)*24-CA7-CB7 -> 2 | CD7: =INT(N7)+TIMEVALUE("18:00") -> 46078.75 | CE7: =IF(CD7>BV7,,(MIN(BV7,CD7)-BU7)*24) | CF7: =IF(BV7-MAX(BU7,CD7)<0,,(BV7-MAX(BU7,CD7))*24) | CG7: =IF($BT7=0,$CF7,) | CH7: =IF($BT7=1,$CE7,) | CI7: =IF($BT7=1,$CF7,)
A8: =IF(ISBLANK(B8),,ROW(A8)-ROW($A$6)) -> 2 | B8: =IFERROR(__xludf.DUMMYFUNCTION("""COMPUTED_VALUE"""),2.0) -> 2 | C8: =IFERROR(__xludf.DUMMYFUNCTION("""COMPUTED_VALUE"""),"QT2025080042") -> QT2025080042 | D8: =IFERROR(__xludf.DUMMYFUNCTION("""COMPUTED_VALUE"""),"บริษัทร้อกเวิธ") -> บริษัทร้อกเวิธ | E8: =IFERROR(__xludf.DUMMYFUNCTION("""COMPUTED_VALUE"""),"TOYOTA บางบ่อHO2") -> TOYOTA บางบ่อHO2 | F8: =IFERROR(__xludf.DUMMYFUNCTION("""COMPUTED_VALUE"""),1.0) -> 1 | M8: =IFERROR(__xludf.DUMMYFUNCTION("""COMPUTED_VALUE"""),"โหลดตู้ Locker") -> โหลดตู้ Locker | N8: =IFERROR(__xludf.DUMMYFUNCTION("""COMPUTED_VALUE"""),46078.0) -> 46078 | O8: =IFERROR(__xludf.DUMMYFUNCTION("""COMPUTED_VALUE"""),0.375) -> 0.375 | P8: =IFERROR(__xludf.DUMMYFUNCTION("""COMPUTED_VALUE"""),46078.0) -> 46078 | Q8: =IFERROR(__xludf.DUMMYFUNCTION("""COMPUTED_VALUE"""),0.7083333333333334) -> 0.70833333 | R8: =IFERROR(__xludf.DUMMYFUNCTION("""COMPUTED_VALUE"""),8.000000000058208) -> 8 | T8: =IFERROR(__xludf.DUMMYFUNCTION("""COMPUTED_VALUE"""),24.000000000174623) -> 24 | U8: =IFERROR(__xludf.DUMMYFUNCTION("""COMPUTED_VALUE"""),3.0) -> 3 | AE8: =IFERROR(__xludf.DUMMYFUNCTION("""COMPUTED_VALUE"""),1.0) -> 1 | AF8: =IFERROR(__xludf.DUMMYFUNCTION("""COMPUTED_VALUE"""),1.0) -> 1 | AT8: =IFERROR(__xludf.DUMMYFUNCTION("""COMPUTED_VALUE"""),1.0) -> 1 | BT8: =IF(ISBLANK(B8),,IF(IFNA(MATCH(N8,List_Holidays,0),0)=0,IF(IFNA(MATCH(WEEKDAY(N8),List_WeekHolidays,0),0),1,0),2)) -> 0 | BU8: =N8+O8 -> 46078.375 | BV8: =P8+Q8 -> 46078.708 | BW8: =IF($BU8>cLunchEnd+$N8,cLunchBegin+$N8+1,cLunchBegin+$N8) -> 46078.5 | BX8: =IF($BU8>cLunchEnd+$N8,cLunchEnd+$N8+1,cLunchEnd+$N8) -> 46078.542 | BY8: =IF($BU8>cDinnerEnd+$N8,cDinnerBegin+$N8+1,cDinnerBegin+$N8) -> 46078.75 | BZ8: =IF($BU8>cDinnerEnd+$N8,cDinnerEnd+$N8+1,cDinnerEnd+$N8) -> 46078.792 | CA8: =IF((MIN($BV8,BX8)-MAX($BU8,BW8))>0,vDurationLunch,) -> 1 | CB8: =IF((MIN($BV8,BZ8)-MAX($BU8,BY8))>0,vDurationDinner,) | CC8: =(BV8-BU8)*24-CA8-CB8 -> 7 | CD8: =INT(N8)+TIMEVALUE("18:00") -> 46078.75 | CE8: =IF(CD8>BV8,,(MIN(BV8,CD8)-BU8)*24) | CF8: =IF(BV8-MAX(BU8,CD8)<0,,(BV8-MAX(BU8,CD8))*24) | CG8: =IF($BT8=0,$CF8,) | CH8: =IF($BT8=1,$CE8,) | CI8: =IF($BT8=1,$CF8,)
A9: =IF(ISBLANK(B9),,ROW(A9)-ROW($A$6)) -> 3 | B9: =IFERROR(__xludf.DUMMYFUNCTION("""COMPUTED_VALUE"""),3.0) -> 3 | C9: =IFERROR(__xludf.DUMMYFUNCTION("""COMPUTED_VALUE"""),"QT2025080042") -> QT2025080042 | D9: =IFERROR(__xludf.DUMMYFUNCTION("""COMPUTED_VALUE"""),"บริษัทร้อกเวิธ") -> บริษัทร้อกเวิธ | E9: =IFERROR(__xludf.DUMMYFUNCTION("""COMPUTED_VALUE"""),"TOYOTA บ้านโพธิ์") -> TOYOTA บ้านโพธิ์ | H9: =IFERROR(__xludf.DUMMYFUNCTION("""COMPUTED_VALUE"""),1.0) -> 1 | M9: =IFERROR(__xludf.DUMMYFUNCTION("""COMPUTED_VALUE"""),"ติดตั้ง ") -> ติดตั้ง | N9: =IFERROR(__xludf.DUMMYFUNCTION("""COMPUTED_VALUE"""),46078.0) -> 46078 | O9: =IFERROR(__xludf.DUMMYFUNCTION("""COMPUTED_VALUE"""),0.6666666666666666) -> 0.66666667 | P9: =IFERROR(__xludf.DUMMYFUNCTION("""COMPUTED_VALUE"""),46079.0) -> 46079 | Q9: =IFERROR(__xludf.DUMMYFUNCTION("""COMPUTED_VALUE"""),0.125) -> 0.125 | R9: =IFERROR(__xludf.DUMMYFUNCTION("""COMPUTED_VALUE"""),11.0) -> 11 | S9: =IFERROR(__xludf.DUMMYFUNCTION("""COMPUTED_VALUE"""),2.0) -> 2 | T9: =IFERROR(__xludf.DUMMYFUNCTION("""COMPUTED_VALUE"""),44.0) -> 44 | U9: =IFERROR(__xludf.DUMMYFUNCTION("""COMPUTED_VALUE"""),4.0) -> 4 | Z9: =IFERROR(__xludf.DUMMYFUNCTION("""COMPUTED_VALUE"""),1.0) -> 1 | AE9: =IFERROR(__xludf.DUMMYFUNCTION("""COMPUTED_VALUE"""),1.0) -> 1 | AH9: =IFERROR(__xludf.DUMMYFUNCTION("""COMPUTED_VALUE"""),1.0) -> 1 | AT9: =IFERROR(__xludf.DUMMYFUNCTION("""COMPUTED_VALUE"""),1.0) -> 1 | BT9: =IF(ISBLANK(B9),,IF(IFNA(MATCH(N9,List_Holidays,0),0)=0,IF(IFNA(MATCH(WEEKDAY(N9),List_WeekHolidays,0),0),1,0),2)) -> 0 | BU9: =N9+O9 -> 46078.667 | BV9: =P9+Q9 -> 46079.125 | BW9: =IF($BU9>cLunchEnd+$N9,cLunchBegin+$N9+1,cLunchBegin+$N9) -> 46079.5 | BX9: =IF($BU9>cLunchEnd+$N9,cLunchEnd+$N9+1,cLunchEnd+$N9) -> 46079.542 | BY9: =IF($BU9>cDinnerEnd+$N9,cDinnerBegin+$N9+1,cDinnerBegin+$N9) -> 46078.75 | BZ9: =IF($BU9>cDinnerEnd+$N9,cDinnerEnd+$N9+1,cDinnerEnd+$N9) -> 46078.792 | CA9: =IF((MIN($BV9,BX9)-MAX($BU9,BW9))>0,vDurationLunch,) | CB9: =IF((MIN($BV9,BZ9)-MAX($BU9,BY9))>0,vDurationDinner,) -> 1 | CC9: =(BV9-BU9)*24-CA9-CB9 -> 10 | CD9: =INT(N9)+TIMEVALUE("18:00") -> 46078.75 | CE9: =IF(CD9>BV9,,(MIN(BV9,CD9)-BU9)*24) -> 2 | CF9: =IF(BV9-MAX(BU9,CD9)<0,,(BV9-MAX(BU9,CD9))*24) -> 9 | CG9: =IF($BT9=0,$CF9,) -> 9 | CH9: =IF($BT9=1,$CE9,) | CI9: =IF($BT9=1,$CF9,)
A10: =IF(ISBLANK(B10),,ROW(A10)-ROW($A$6)) -> 4 | B10: =IFERROR(__xludf.DUMMYFUNCTION("""COMPUTED_VALUE"""),4.0) -> 4 | C10: =IFERROR(__xludf.DUMMYFUNCTION("""COMPUTED_VALUE"""),"QT2025090063") -> QT2025090063 | D10: =IFERROR(__xludf.DUMMYFUNCTION("""COMPUTED_VALUE"""),"บริษัทโอคามูระ") -> บริษัทโอคามูระ | E10: =IFERROR(__xludf.DUMMYFUNCTION("""COMPUTED_VALUE"""),"TOYOTA บางบ่อ HO2") -> TOYOTA บางบ่อ HO2 | L10: =IFERROR(__xludf.DUMMYFUNCTION("""COMPUTED_VALUE"""),1.0) -> 1 | M10: =IFERROR(__xludf.DUMMYFUNCTION("""COMPUTED_VALUE"""),"ส่งเก้าอี้ เก้าอี้โต๊ะประชุม8 / เก้าอี้ทำงาน 162 / EVP-พาทิชั่น 2") -> ส่งเก้าอี้ เก้าอี้โต๊ะประชุม8 / เก้าอี้ทำงาน 162 / EVP-พาทิชั่น 2 | N10: =IFERROR(__xludf.DUMMYFUNCTION("""COMPUTED_VALUE"""),46078.0) -> 46078 | P10: =IFERROR(__xludf.DUMMYFUNCTION("""COMPUTED_VALUE"""),46078.0) -> 46078 | U10: =IFERROR(__xludf.DUMMYFUNCTION("""COMPUTED_VALUE"""),3.0) -> 3 | Y10: =IFERROR(__xludf.DUMMYFUNCTION("""COMPUTED_VALUE"""),1.0) -> 1 | AH10: =IFERROR(__xludf.DUMMYFUNCTION("""COMPUTED_VALUE"""),1.0) -> 1 | AK10: =IFERROR(__xludf.DUMMYFUNCTION("""COMPUTED_VALUE"""),1.0) -> 1 | BT10: =IF(ISBLANK(B10),,IF(IFNA(MATCH(N10,List_Holidays,0),0)=0,IF(IFNA(MATCH(WEEKDAY(N10),List_WeekHolidays,0),0),1,0),2)) -> 0 | BU10: =N10+O10 -> 46078 | BV10: =P10+Q10 -> 46078 | BW10: =IF($BU10>cLunchEnd+$N10,cLunchBegin+$N10+1,cLunchBegin+$N10) -> 46078.5 | BX10: =IF($BU10>cLunchEnd+$N10,cLunchEnd+$N10+1,cLunchEnd+$N10) -> 46078.542 | BY10: =IF($BU10>cDinnerEnd+$N10,cDinnerBegin+$N10+1,cDinnerBegin+$N10) -> 46078.75 | BZ10: =IF($BU10>cDinnerEnd+$N10,cDinnerEnd+$N10+1,cDinnerEnd+$N10) -> 46078.792 | CA10: =IF((MIN($BV10,BX10)-MAX($BU10,BW10))>0,vDurationLunch,) | CB10: =IF((MIN($BV10,BZ10)-MAX($BU10,BY10))>0,vDurationDinner,) | CC10: =(BV10-BU10)*24-CA10-CB10 -> 0 | CD10: =INT(N10)+TIMEVALUE("18:00") -> 46078.75 | CE10: =IF(CD10>BV10,,(MIN(BV10,CD10)-BU10)*24) | CF10: =IF(BV10-MAX(BU10,CD10)<0,,(BV10-MAX(BU10,CD10))*24) | CG10: =IF($BT10=0,$CF10,) | CH10: =IF($BT10=1,$CE10,) | CI10: =IF($BT10=1,$CF10,)
A11: =IF(ISBLANK(B11),,ROW(A11)-ROW($A$6)) -> 5 | B11: =IFERROR(__xludf.DUMMYFUNCTION("""COMPUTED_VALUE"""),5.0) -> 5 | C11: =IFERROR(__xludf.DUMMYFUNCTION("""COMPUTED_VALUE"""),"QT2025120083-QT2026020053") -> QT2025120083-QT2026020053 | D11: =IFERROR(__xludf.DUMMYFUNCTION("""COMPUTED_VALUE"""),"บริษัทร้อกเวิธ") -> บริษัทร้อกเวิธ | E11: =IFERROR(__xludf.DUMMYFUNCTION("""COMPUTED_VALUE"""),"Space Matrix Design / PJ. Galderma Thailand") -> Space Matrix Design / PJ. Galderma Thailand | H11: =IFERROR(__xludf.DUMMYFUNCTION("""COMPUTED_VALUE"""),1.0) -> 1 | M11: =IFERROR(__xludf.DUMMYFUNCTION("""COMPUTED_VALUE"""),"ต้องจบงาน!") -> ต้องจบงาน! | N11: =IFERROR(__xludf.DUMMYFUNCTION("""COMPUTED_VALUE"""),46078.0) -> 46078 | P11: =IFERROR(__xludf.DUMMYFUNCTION("""COMPUTED_VALUE"""),46078.0) -> 46078 | T11: =IFERROR(__xludf.DUMMYFUNCTION("""COMPUTED_VALUE"""),0.0) -> 0 | U11: =IFERROR(__xludf.DUMMYFUNCTION("""COMPUTED_VALUE"""),6.0) -> 6 | AL11: =IFERROR(__xludf.DUMMYFUNCTION("""COMPUTED_VALUE"""),1.0) -> 1 | AN11: =IFERROR(__xludf.DUMMYFUNCTION("""COMPUTED_VALUE"""),1.0) -> 1 | AO11: =IFERROR(__xludf.DUMMYFUNCTION("""COMPUTED_VALUE"""),1.0) -> 1 | AS11: =IFERROR(__xludf.DUMMYFUNCTION("""COMPUTED_VALUE"""),1.0) -> 1 | AV11: =IFERROR(__xludf.DUMMYFUNCTION("""COMPUTED_VALUE"""),1.0) -> 1 | AX11: =IFERROR(__xludf.DUMMYFUNCTION("""COMPUTED_VALUE"""),1.0) -> 1 | BT11: =IF(ISBLANK(B11),,IF(IFNA(MATCH(N11,List_Holidays,0),0)=0,IF(IFNA(MATCH(WEEKDAY(N11),List_WeekHolidays,0),0),1,0),2)) -> 0 | BU11: =N11+O11 -> 46078 | BV11: =P11+Q11 -> 46078 | BW11: =IF($BU11>cLunchEnd+$N11,cLunchBegin+$N11+1,cLunchBegin+$N11) -> 46078.5 | BX11: =IF($BU11>cLunchEnd+$N11,cLunchEnd+$N11+1,cLunchEnd+$N11) -> 46078.542 | BY11: =IF($BU11>cDinnerEnd+$N11,cDinnerBegin+$N11+1,cDinnerBegin+$N11) -> 46078.75 | BZ11: =IF($BU11>cDinnerEnd+$N11,cDinnerEnd+$N11+1,cDinnerEnd+$N11) -> 46078.792 | CA11: =IF((MIN($BV11,BX11)-MAX($BU11,BW11))>0,vDurationLunch,) | CB11: =IF((MIN($BV11,BZ11)-MAX($BU11,BY11))>0,vDurationDinner,) | CC11: =(BV11-BU11)*24-CA11-CB11 -> 0 | CD11: =INT(N11)+TIMEVALUE("18:00") -> 46078.75 | CE11: =IF(CD11>BV11,,(MIN(BV11,CD11)-BU11)*24) | CF11: =IF(BV11-MAX(BU11,CD11)<0,,(BV11-MAX(BU11,CD11))*24) | CG11: =IF($BT11=0,$CF11,) | CH11: =IF($BT11=1,$CE11,) | CI11: =IF($BT11=1,$CF11,)
A12: =IF(ISBLANK(B12),,ROW(A12)-ROW($A$6)) -> 6 | B12: =IFERROR(__xludf.DUMMYFUNCTION("""COMPUTED_VALUE"""),6.0) -> 6 | D12: =IFERROR(__xludf.DUMMYFUNCTION("""COMPUTED_VALUE"""),"บริษัทโอคามูระ") -> บริษัทโอคามูระ | E12: =IFERROR(__xludf.DUMMYFUNCTION("""COMPUTED_VALUE"""),"GSK One ดุสิต ชั้น 25") -> GSK One ดุสิต ชั้น 25 | K12: =IFERROR(__xludf.DUMMYFUNCTION("""COMPUTED_VALUE"""),1.0) -> 1 | M12: =IFERROR(__xludf.DUMMYFUNCTION("""COMPUTED_VALUE"""),"มาร์กไลน์") -> มาร์กไลน์ | N12: =IFERROR(__xludf.DUMMYFUNCTION("""COMPUTED_VALUE"""),46078.0) -> 46078 | P12: =IFERROR(__xludf.DUMMYFUNCTION("""COMPUTED_VALUE"""),46078.0) -> 46078 | T12: =IFERROR(__xludf.DUMMYFUNCTION("""COMPUTED_VALUE"""),0.0) -> 0 | U12: =IFERROR(__xludf.DUMMYFUNCTION("""COMPUTED_VALUE"""),1.0) -> 1 | AR12: =IFERROR(__xludf.DUMMYFUNCTION("""COMPUTED_VALUE"""),1.0) -> 1 | BT12: =IF(ISBLANK(B12),,IF(IFNA(MATCH(N12,List_Holidays,0),0)=0,IF(IFNA(MATCH(WEEKDAY(N12),List_WeekHolidays,0),0),1,0),2)) -> 0 | BU12: =N12+O12 -> 46078 | BV12: =P12+Q12 -> 46078 | BW12: =IF($BU12>cLunchEnd+$N12,cLunchBegin+$N12+1,cLunchBegin+$N12) -> 46078.5 | BX12: =IF($BU12>cLunchEnd+$N12,cLunchEnd+$N12+1,cLunchEnd+$N12) -> 46078.542 | BY12: =IF($BU12>cDinnerEnd+$N12,cDinnerBegin+$N12+1,cDinnerBegin+$N12) -> 46078.75 | BZ12: =IF($BU12>cDinnerEnd+$N12,cDinnerEnd+$N12+1,cDinnerEnd+$N12) -> 46078.792 | CA12: =IF((MIN($BV12,BX12)-MAX($BU12,BW12))>0,vDurationLunch,) | CB12: =IF((MIN($BV12,BZ12)-MAX($BU12,BY12))>0,vDurationDinner,) | CC12: =(BV12-BU12)*24-CA12-CB12 -> 0 | CD12: =INT(N12)+TIMEVALUE("18:00") -> 46078.75 | CE12: =IF(CD12>BV12,,(MIN(BV12,CD12)-BU12)*24) | CF12: =IF(BV12-MAX(BU12,CD12)<0,,(BV12-MAX(BU12,CD12))*24) | CG12: =IF($BT12=0,$CF12,) | CH12: =IF($BT12=1,$CE12,) | CI12: =IF($BT12=1,$CF12,)
A13: =IF(ISBLANK(B13),,ROW(A13)-ROW($A$6)) -> 7 | B13: =IFERROR(__xludf.DUMMYFUNCTION("""COMPUTED_VALUE"""),7.0) -> 7 | C13: =IFERROR(__xludf.DUMMYFUNCTION("""COMPUTED_VALUE"""),"QT2026010080") -> QT2026010080 | D13: =IFERROR(__xludf.DUMMYFUNCTION("""COMPUTED_VALUE"""),"บริษัทร้อกเวิธ") -> บริษัทร้อกเวิธ | E13: =IFERROR(__xludf.DUMMYFUNCTION("""COMPUTED_VALUE"""),"บริษัท เงินทุนแอร์ดวาน ") -> บริษัท เงินทุนแอร์ดวาน | L13: =IFERROR(__xludf.DUMMYFUNCTION("""COMPUTED_VALUE"""),1.0) -> 1 | M13: =IFERROR(__xludf.DUMMYFUNCTION("""COMPUTED_VALUE"""),"ส่งเก้าอี้ที่ร้านเบาะกิติธร") -> ส่งเก้าอี้ที่ร้านเบาะกิติธร | N13: =IFERROR(__xludf.DUMMYFUNCTION("""COMPUTED_VALUE"""),46078.0) -> 46078 | O13: =IFERROR(__xludf.DUMMYFUNCTION("""COMPUTED_VALUE"""),0.75) -> 0.75 | P13: =IFERROR(__xludf.DUMMYFUNCTION("""COMPUTED_VALUE"""),46078.0) -> 46078 | Q13: =IFERROR(__xludf.DUMMYFUNCTION("""COMPUTED_VALUE"""),0.041666666666666664) -> 0.041666667 | R13: =IFERROR(__xludf.DUMMYFUNCTION("""COMPUTED_VALUE"""),-17.000000000058208) -> -17 | T13: =IFERROR(__xludf.DUMMYFUNCTION("""COMPUTED_VALUE"""),-17.000000000058208) -> -17 | U13: =IFERROR(__xludf.DUMMYFUNCTION("""COMPUTED_VALUE"""),1.0) -> 1 | AR13: =IFERROR(__xludf.DUMMYFUNCTION("""COMPUTED_VALUE"""),1.0) -> 1 | BT13: =IF(ISBLANK(B13),,IF(IFNA(MATCH(N13,List_Holidays,0),0)=0,IF(IFNA(MATCH(WEEKDAY(N13),List_WeekHolidays,0),0),1,0),2)) -> 0 | BU13: =N13+O13 -> 46078.75 | BV13: =P13+Q13 -> 46078.042 | BW13: =IF($BU13>cLunchEnd+$N13,cLunchBegin+$N13+1,cLunchBegin+$N13) -> 46079.5 | BX13: =IF($BU13>cLunchEnd+$N13,cLunchEnd+$N13+1,cLunchEnd+$N13) -> 46079.542 | BY13: =IF($BU13>cDinnerEnd+$N13,cDinnerBegin+$N13+1,cDinnerBegin+$N13) -> 46078.75 | BZ13: =IF($BU13>cDinnerEnd+$N13,cDinnerEnd+$N13+1,cDinnerEnd+$N13) -> 46078.792 | CA13: =IF((MIN($BV13,BX13)-MAX($BU13,BW13))>0,vDurationLunch,) | CB13: =IF((MIN($BV13,BZ13)-MAX($BU13,BY13))>0,vDurationDinner,) | CC13: =(BV13-BU13)*24-CA13-CB13 -> -17 | CD13: =INT(N13)+TIMEVALUE("18:00") -> 46078.75 | CE13: =IF(CD13>BV13,,(MIN(BV13,CD13)-BU13)*24) | CF13: =IF(BV13-MAX(BU13,CD13)<0,,(BV13-MAX(BU13,CD13))*24) | CG13: =IF($BT13=0,$CF13,) | CH13: =IF($BT13=1,$CE13,) | CI13: =IF($BT13=1,$CF13,)
A14: =IF(ISBLANK(B14),,ROW(A14)-ROW($A$6)) -> 8 | B14: =IFERROR(__xludf.DUMMYFUNCTION("""COMPUTED_VALUE"""),8.0) -> 8 | D14: =IFERROR(__xludf.DUMMYFUNCTION("""COMPUTED_VALUE"""),"บริษัทร้อกเวิธ") -> บริษัทร้อกเวิธ | E14: =IFERROR(__xludf.DUMMYFUNCTION("""COMPUTED_VALUE"""),"TOYOTA AUTO") -> TOYOTA AUTO | K14: =IFERROR(__xludf.DUMMYFUNCTION("""COMPUTED_VALUE"""),1.0) -> 1 | M14: =IFERROR(__xludf.DUMMYFUNCTION("""COMPUTED_VALUE"""),"มาร์กไลน์") -> มาร์กไลน์ | N14: =IFERROR(__xludf.DUMMYFUNCTION("""COMPUTED_VALUE"""),46079.0) -> 46079 | O14: =IFERROR(__xludf.DUMMYFUNCTION("""COMPUTED_VALUE"""),0.375) -> 0.375 | P14: =IFERROR(__xludf.DUMMYFUNCTION("""COMPUTED_VALUE"""),46079.0) -> 46079 | Q14: =IFERROR(__xludf.DUMMYFUNCTION("""COMPUTED_VALUE"""),0.7083333333333334) -> 0.70833333 | R14: =IFERROR(__xludf.DUMMYFUNCTION("""COMPUTED_VALUE"""),8.000000000058208) -> 8 | T14: =IFERROR(__xludf.DUMMYFUNCTION("""COMPUTED_VALUE"""),0.0) -> 0 | U14: =IFERROR(__xludf.DUMMYFUNCTION("""COMPUTED_VALUE"""),0.0) -> 0 | BT14: =IF(ISBLANK(B14),,IF(IFNA(MATCH(N14,List_Holidays,0),0)=0,IF(IFNA(MATCH(WEEKDAY(N14),List_WeekHolidays,0),0),1,0),2)) -> 0 | BU14: =N14+O14 -> 46079.375 | BV14: =P14+Q14 -> 46079.708 | BW14: =IF($BU14>cLunchEnd+$N14,cLunchBegin+$N14+1,cLunchBegin+$N14) -> 46079.5 | BX14: =IF($BU14>cLunchEnd+$N14,cLunchEnd+$N14+1,cLunchEnd+$N14) -> 46079.542 | BY14: =IF($BU14>cDinnerEnd+$N14,cDinnerBegin+$N14+1,cDinnerBegin+$N14) -> 46079.75 | BZ14: =IF($BU14>cDinnerEnd+$N14,cDinnerEnd+$N14+1,cDinnerEnd+$N14) -> 46079.792 | CA14: =IF((MIN($BV14,BX14)-MAX($BU14,BW14))>0,vDurationLunch,) -> 1 | CB14: =IF((MIN($BV14,BZ14)-MAX($BU14,BY14))>0,vDurationDinner,) | CC14: =(BV14-BU14)*24-CA14-CB14 -> 7 | CD14: =INT(N14)+TIMEVALUE("18:00") -> 46079.75 | CE14: =IF(CD14>BV14,,(MIN(BV14,CD14)-BU14)*24) | CF14: =IF(BV14-MAX(BU14,CD14)<0,,(BV14-MAX(BU14,CD14))*24) | CG14: =IF($BT14=0,$CF14,) | CH14: =IF($BT14=1,$CE14,) | CI14: =IF($BT14=1,$CF14,)
A15: =IF(ISBLANK(B15),,ROW(A15)-ROW($A$6)) -> 9 | B15: =IFERROR(__xludf.DUMMYFUNCTION("""COMPUTED_VALUE"""),9.0) -> 9 | C15: =IFERROR(__xludf.DUMMYFUNCTION("""COMPUTED_VALUE"""),"QT2026020004") -> QT2026020004 | D15: =IFERROR(__xludf.DUMMYFUNCTION("""COMPUTED_VALUE"""),"บริษัทโอคามูระ") -> บริษัทโอคามูระ | E15: =IFERROR(__xludf.DUMMYFUNCTION("""COMPUTED_VALUE"""),"เดลีเทค อาคารThr Parq พระราม4") -> เดลีเทค อาคารThr Parq พระราม4 | F15: =IFERROR(__xludf.DUMMYFUNCTION("""COMPUTED_VALUE"""),1.0) -> 1 | M15: =IFERROR(__xludf.DUMMYFUNCTION("""COMPUTED_VALUE"""),"จัมโบ้+กะบะ (รับของปู่เจ้า14.00 ส่งหน้างานได้หลัง18.00น. )") -> จัมโบ้+กะบะ (รับของปู่เจ้า14.00 ส่งหน้างานได้หลัง18.00น. ) | N15: =IFERROR(__xludf.DUMMYFUNCTION("""COMPUTED_VALUE"""),46078.0) -> 46078 | P15: =IFERROR(__xludf.DUMMYFUNCTION("""COMPUTED_VALUE"""),46078.0) -> 46078 | T15: =IFERROR(__xludf.DUMMYFUNCTION("""COMPUTED_VALUE"""),0.0) -> 0 | U15: =IFERROR(__xludf.DUMMYFUNCTION("""COMPUTED_VALUE"""),7.0) -> 7 | AL15: =IFERROR(__xludf.DUMMYFUNCTION("""COMPUTED_VALUE"""),1.0) -> 1 | AN15: =IFERROR(__xludf.DUMMYFUNCTION("""COMPUTED_VALUE"""),1.0) -> 1 | AO15: =IFERROR(__xludf.DUMMYFUNCTION("""COMPUTED_VALUE"""),1.0) -> 1 | AR15: =IFERROR(__xludf.DUMMYFUNCTION("""COMPUTED_VALUE"""),1.0) -> 1 | AS15: =IFERROR(__xludf.DUMMYFUNCTION("""COMPUTED_VALUE"""),1.0) -> 1 | AV15: =IFERROR(__xludf.DUMMYFUNCTION("""COMPUTED_VALUE"""),1.0) -> 1 | AX15: =IFERROR(__xludf.DUMMYFUNCTION("""COMPUTED_VALUE"""),1.0) -> 1 | BT15: =IF(ISBLANK(B15),,IF(IFNA(MATCH(N15,List_Holidays,0),0)=0,IF(IFNA(MATCH(WEEKDAY(N15),List_WeekHolidays,0),0),1,0),2)) -> 0 | BU15: =N15+O15 -> 46078 | BV15: =P15+Q15 -> 46078 | BW15: =IF($BU15>cLunchEnd+$N15,cLunchBegin+$N15+1,cLunchBegin+$N15) -> 46078.5 | BX15: =IF($BU15>cLunchEnd+$N15,cLunchEnd+$N15+1,cLunchEnd+$N15) -> 46078.542 | BY15: =IF($BU15>cDinnerEnd+$N15,cDinnerBegin+$N15+1,cDinnerBegin+$N15) -> 46078.75 | BZ15: =IF($BU15>cDinnerEnd+$N15,cDinnerEnd+$N15+1,cDinnerEnd+$N15) -> 46078.792 | CA15: =IF((MIN($BV15,BX15)-MAX($BU15,BW15))>0,vDurationLunch,) | CB15: =IF((MIN($BV15,BZ15)-MAX($BU15,BY15))>0,vDurationDinner,) | CC15: =(BV15-BU15)*24-CA15-CB15 -> 0 | CD15: =INT(N15)+TIMEVALUE("18:00") -> 46078.75 | CE15: =IF(CD15>BV15,,(MIN(BV15,CD15)-BU15)*24) | CF15: =IF(BV15-MAX(BU15,CD15)<0,,(BV15-MAX(BU15,CD15))*24) | CG15: =IF($BT15=0,$CF15,) | CH15: =IF($BT15=1,$CE15,) | CI15: =IF($BT15=1,$CF15,)
A16: =IF(ISBLANK(B16),,ROW(A16)-ROW($A$6)) -> 10 | B16: =IFERROR(__xludf.DUMMYFUNCTION("""COMPUTED_VALUE"""),10.0) -> 10 | C16: =IFERROR(__xludf.DUMMYFUNCTION("""COMPUTED_VALUE"""),"QT2025070009") -> QT2025070009 | D16: =IFERROR(__xludf.DUMMYFUNCTION("""COMPUTED_VALUE"""),"บริษัทร้อกเวิธ") -> บริษัทร้อกเวิธ | E16: =IFERROR(__xludf.DUMMYFUNCTION("""COMPUTED_VALUE"""),"การบินไทย Phas1 อาคาร 5 ชั้น 18") -> การบินไทย Phas1 อาคาร 5 ชั้น 18 | L16: =IFERROR(__xludf.DUMMYFUNCTION("""COMPUTED_VALUE"""),1.0) -> 1 | M16: =IFERROR(__xludf.DUMMYFUNCTION("""COMPUTED_VALUE"""),"ส่งงานกับทางการบิน ") -> ส่งงานกับทางการบิน | N16: =IFERROR(__xludf.DUMMYFUNCTION("""COMPUTED_VALUE"""),46078.0) -> 46078 | O16: =IFERROR(__xludf.DUMMYFUNCTION("""COMPUTED_VALUE"""),0.75) -> 0.75 | P16: =IFERROR(__xludf.DUMMYFUNCTION("""COMPUTED_VALUE"""),46078.0) -> 46078 | Q16: =IFERROR(__xludf.DUMMYFUNCTION("""COMPUTED_VALUE"""),0.875) -> 0.875 | R16: =IFERROR(__xludf.DUMMYFUNCTION("""COMPUTED_VALUE"""),3.0) -> 3 | T16: =IFERROR(__xludf.DUMMYFUNCTION("""COMPUTED_VALUE"""),9.0) -> 9 | U16: =IFERROR(__xludf.DUMMYFUNCTION("""COMPUTED_VALUE"""),3.0) -> 3 | AG16: =IFERROR(__xludf.DUMMYFUNCTION("""COMPUTED_VALUE"""),1.0) -> 1 | AY16: =IFERROR(__xludf.DUMMYFUNCTION("""COMPUTED_VALUE"""),1.0) -> 1 | BA16: =IFERROR(__xludf.DUMMYFUNCTION("""COMPUTED_VALUE"""),1.0) -> 1 | BT16: =IF(ISBLANK(B16),,IF(IFNA(MATCH(N16,List_Holidays,0),0)=0,IF(IFNA(MATCH(WEEKDAY(N16),List_WeekHolidays,0),0),1,0),2)) -> 0 | BU16: =N16+O16 -> 46078.75 | BV16: =P16+Q16 -> 46078.875 | BW16: =IF($BU16>cLunchEnd+$N16,cLunchBegin+$N16+1,cLunchBegin+$N16) -> 46079.5 | BX16: =IF($BU16>cLunchEnd+$N16,cLunchEnd+$N16+1,cLunchEnd+$N16) -> 46079.542 | BY16: =IF($BU16>cDinnerEnd+$N16,cDinnerBegin+$N16+1,cDinnerBegin+$N16) -> 46078.75 | BZ16: =IF($BU16>cDinnerEnd+$N16,cDinnerEnd+$N16+1,cDinnerEnd+$N16) -> 46078.792 | CA16: =IF((MIN($BV16,BX16)-MAX($BU16,BW16))>0,vDurationLunch,) | CB16: =IF((MIN($BV16,BZ16)-MAX($BU16,BY16))>0,vDurationDinner,) -> 1 | CC16: =(BV16-BU16)*24-CA16-CB16 -> 2 | CD16: =INT(N16)+TIMEVALUE("18:00") -> 46078.75 | CE16: =IF(CD16>BV16,,(MIN(BV16,CD16)-BU16)*24) -> 0 | CF16: =IF(BV16-MAX(BU16,CD16)<0,,(BV16-MAX(BU16,CD16))*24) -> 3 | CG16: =IF($BT16=0,$CF16,) -> 3 | CH16: =IF($BT16=1,$CE16,) | CI16: =IF($BT16=1,$CF16,)
A17: =IF(ISBLANK(B17),,ROW(A17)-ROW($A$6)) -> 11 | B17: =IFERROR(__xludf.DUMMYFUNCTION("""COMPUTED_VALUE"""),11.0) -> 11 | D17: =IFERROR(__xludf.DUMMYFUNCTION("""COMPUTED_VALUE"""),"บริษัทร้อกเวิธ") -> บริษัทร้อกเวิธ | E17: =IFERROR(__xludf.DUMMYFUNCTION("""COMPUTED_VALUE"""),"RW วางบิล") -> RW วางบิล | L17: =IFERROR(__xludf.DUMMYFUNCTION("""COMPUTED_VALUE"""),1.0) -> 1 | M17: =IFERROR(__xludf.DUMMYFUNCTION("""COMPUTED_VALUE"""),"วางบิลก่อนเที่ยง") -> วางบิลก่อนเที่ยง | N17: =IFERROR(__xludf.DUMMYFUNCTION("""COMPUTED_VALUE"""),46078.0) -> 46078 | P17: =IFERROR(__xludf.DUMMYFUNCTION("""COMPUTED_VALUE"""),46078.0) -> 46078 | T17: =IFERROR(__xludf.DUMMYFUNCTION("""COMPUTED_VALUE"""),0.0) -> 0 | U17: =IFERROR(__xludf.DUMMYFUNCTION("""COMPUTED_VALUE"""),1.0) -> 1 | AY17: =IFERROR(__xludf.DUMMYFUNCTION("""COMPUTED_VALUE"""),1.0) -> 1 | BT17: =IF(ISBLANK(B17),,IF(IFNA(MATCH(N17,List_Holidays,0),0)=0,IF(IFNA(MATCH(WEEKDAY(N17),List_WeekHolidays,0),0),1,0),2)) -> 0 | BU17: =N17+O17 -> 46078 | BV17: =P17+Q17 -> 46078 | BW17: =IF($BU17>cLunchEnd+$N17,cLunchBegin+$N17+1,cLunchBegin+$N17) -> 46078.5 | BX17: =IF($BU17>cLunchEnd+$N17,cLunchEnd+$N17+1,cLunchEnd+$N17) -> 46078.542 | BY17: =IF($BU17>cDinnerEnd+$N17,cDinnerBegin+$N17+1,cDinnerBegin+$N17) -> 46078.75 | BZ17: =IF($BU17>cDinnerEnd+$N17,cDinnerEnd+$N17+1,cDinnerEnd+$N17) -> 46078.792 | CA17: =IF((MIN($BV17,BX17)-MAX($BU17,BW17))>0,vDurationLunch,) | CB17: =IF((MIN($BV17,BZ17)-MAX($BU17,BY17))>0,vDurationDinner,) | CC17: =(BV17-BU17)*24-CA17-CB17 -> 0 | CD17: =INT(N17)+TIMEVALUE("18:00") -> 46078.75 | CE17: =IF(CD17>BV17,,(MIN(BV17,CD17)-BU17)*24) | CF17: =IF(BV17-MAX(BU17,CD17)<0,,(BV17-MAX(BU17,CD17))*24) | CG17: =IF($BT17=0,$CF17,) | CH17: =IF($BT17=1,$CE17,) | CI17: =IF($BT17=1,$CF17,)
A18: =IF(ISBLANK(B18),,ROW(A18)-ROW($A$6)) -> 12 | B18: =IFERROR(__xludf.DUMMYFUNCTION("""COMPUTED_VALUE"""),12.0) -> 12 | D18: =IFERROR(__xludf.DUMMYFUNCTION("""COMPUTED_VALUE"""),"บริษัทโอคามูระ") -> บริษัทโอคามูระ | E18: =IFERROR(__xludf.DUMMYFUNCTION("""COMPUTED_VALUE"""),"โอคามูระ") -> โอคามูระ | L18: =IFERROR(__xludf.DUMMYFUNCTION("""COMPUTED_VALUE"""),1.0) -> 1 | M18: =IFERROR(__xludf.DUMMYFUNCTION("""COMPUTED_VALUE"""),"รับเช็คโอคามูระ 14.00-16.00 น. ") -> รับเช็คโอคามูระ 14.00-16.00 น. | N18: =IFERROR(__xludf.DUMMYFUNCTION("""COMPUTED_VALUE"""),46078.0) -> 46078 | O18: =IFERROR(__xludf.DUMMYFUNCTION("""COMPUTED_VALUE"""),0.375) -> 0.375 | P18: =IFERROR(__xludf.DUMMYFUNCTION("""COMPUTED_VALUE"""),46078.0) -> 46078 | Q18: =IFERROR(__xludf.DUMMYFUNCTION("""COMPUTED_VALUE"""),0.5) -> 0.5 | R18: =IFERROR(__xludf.DUMMYFUNCTION("""COMPUTED_VALUE"""),3.0) -> 3 | T18: =IFERROR(__xludf.DUMMYFUNCTION("""COMPUTED_VALUE"""),3.0) -> 3 | U18: =IFERROR(__xludf.DUMMYFUNCTION("""COMPUTED_VALUE"""),1.0) -> 1 | AY18: =IFERROR(__xludf.DUMMYFUNCTION("""COMPUTED_VALUE"""),1.0) -> 1 | BT18: =IF(ISBLANK(B18),,IF(IFNA(MATCH(N18,List_Holidays,0),0)=0,IF(IFNA(MATCH(WEEKDAY(N18),List_WeekHolidays,0),0),1,0),2)) -> 0 | BU18: =N18+O18 -> 46078.375 | BV18: =P18+Q18 -> 46078.5 | BW18: =IF($BU18>cLunchEnd+$N18,cLunchBegin+$N18+1,cLunchBegin+$N18) -> 46078.5 | BX18: =IF($BU18>cLunchEnd+$N18,cLunchEnd+$N18+1,cLunchEnd+$N18) -> 46078.542 | BY18: =IF($BU18>cDinnerEnd+$N18,cDinnerBegin+$N18+1,cDinnerBegin+$N18) -> 46078.75 | BZ18: =IF($BU18>cDinnerEnd+$N18,cDinnerEnd+$N18+1,cDinnerEnd+$N18) -> 46078.792 | CA18: =IF((MIN($BV18,BX18)-MAX($BU18,BW18))>0,vDurationLunch,) | CB18: =IF((MIN($BV18,BZ18)-MAX($BU18,BY18))>0,vDurationDinner,) | CC18: =(BV18-BU18)*24-CA18-CB18 -> 3 | CD18: =INT(N18)+TIMEVALUE("18:00") -> 46078.75 | CE18: =IF(CD18>BV18,,(MIN(BV18,CD18)-BU18)*24) | CF18: =IF(BV18-MAX(BU18,CD18)<0,,(BV18-MAX(BU18,CD18))*24) | CG18: =IF($BT18=0,$CF18,) | CH18: =IF($BT18=1,$CE18,) | CI18: =IF($BT18=1,$CF18,)
A19: =IF(ISBLANK(B19),,ROW(A19)-ROW($A$6)) -> 13 | B19: =IFERROR(__xludf.DUMMYFUNCTION("""COMPUTED_VALUE"""),13.0) -> 13 | C19: =IFERROR(__xludf.DUMMYFUNCTION("""COMPUTED_VALUE"""),"QT2025080042") -> QT2025080042 | D19: =IFERROR(__xludf.DUMMYFUNCTION("""COMPUTED_VALUE"""),"บริษัทร้อกเวิธ") -> บริษัทร้อกเวิธ | E19: =IFERROR(__xludf.DUMMYFUNCTION("""COMPUTED_VALUE""")," TOYOTA บางบ่อHO2") -> TOYOTA บางบ่อHO2 | H19: =IFERROR(__xludf.DUMMYFUNCTION("""COMPUTED_VALUE"""),1.0) -> 1 | M19: =IFERROR(__xludf.DUMMYFUNCTION("""COMPUTED_VALUE""")," ติดตั้งชุดโต๊ะทำงาน ") -> ติดตั้งชุดโต๊ะทำงาน | N19: =IFERROR(__xludf.DUMMYFUNCTION("""COMPUTED_VALUE"""),46079.0) -> 46079 | O19: =IFERROR(__xludf.DUMMYFUNCTION("""COMPUTED_VALUE"""),0.2916666666666667) -> 0.29166667 | P19: =IFERROR(__xludf.DUMMYFUNCTION("""COMPUTED_VALUE"""),46079.0) -> 46079 | Q19: =IFERROR(__xludf.DUMMYFUNCTION("""COMPUTED_VALUE"""),0.8333333333333334) -> 0.83333333 | R19: =IFERROR(__xludf.DUMMYFUNCTION("""COMPUTED_VALUE"""),13.000000000058206) -> 13 | T19: =IFERROR(__xludf.DUMMYFUNCTION("""COMPUTED_VALUE"""),91.00000000040744) -> 91 | U19: =IFERROR(__xludf.DUMMYFUNCTION("""COMPUTED_VALUE"""),7.0) -> 7 | V19: =IFERROR(__xludf.DUMMYFUNCTION("""COMPUTED_VALUE"""),1.0) -> 1 | W19: =IFERROR(__xludf.DUMMYFUNCTION("""COMPUTED_VALUE"""),1.0) -> 1 | Y19: =IFERROR(__xludf.DUMMYFUNCTION("""COMPUTED_VALUE"""),1.0) -> 1 | AA19: =IFERROR(__xludf.DUMMYFUNCTION("""COMPUTED_VALUE"""),1.0) -> 1 | AK19: =IFERROR(__xludf.DUMMYFUNCTION("""COMPUTED_VALUE"""),1.0) -> 1 | AT19: =IFERROR(__xludf.DUMMYFUNCTION("""COMPUTED_VALUE"""),1.0) -> 1 | AW19: =IFERROR(__xludf.DUMMYFUNCTION("""COMPUTED_VALUE"""),1.0) -> 1 | BT19: =IF(ISBLANK(B19),,IF(IFNA(MATCH(N19,List_Holidays,0),0)=0,IF(IFNA(MATCH(WEEKDAY(N19),List_WeekHolidays,0),0),1,0),2)) -> 0 | BU19: =N19+O19 -> 46079.292 | BV19: =P19+Q19 -> 46079.833 | BW19: =IF($BU19>cLunchEnd+$N19,cLunchBegin+$N19+1,cLunchBegin+$N19) -> 46079.5 | BX19: =IF($BU19>cLunchEnd+$N19,cLunchEnd+$N19+1,cLunchEnd+$N19) -> 46079.542 | BY19: =IF($BU19>cDinnerEnd+$N19,cDinnerBegin+$N19+1,cDinnerBegin+$N19) -> 46079.75 | BZ19: =IF($BU19>cDinnerEnd+$N19,cDinnerEnd+$N19+1,cDinnerEnd+$N19) -> 46079.792 | CA19: =IF((MIN($BV19,BX19)-MAX($BU19,BW19))>0,vDurationLunch,) -> 1 | CB19: =IF((MIN($BV19,BZ19)-MAX($BU19,BY19))>0,vDurationDinner,) -> 1 | CC19: =(BV19-BU19)*24-CA19-CB19 -> 11 | CD19: =INT(N19)+TIMEVALUE("18:00") -> 46079.75 | CE19: =IF(CD19>BV19,,(MIN(BV19,CD19)-BU19)*24) -> 11 | CF19: =IF(BV19-MAX(BU19,CD19)<0,,(BV19-MAX(BU19,CD19))*24) -> 2 | CG19: =IF($BT19=0,$CF19,) -> 2 | CH19: =IF($BT19=1,$CE19,) | CI19: =IF($BT19=1,$CF19,)
